Workbook

Sheet Guide
A1: Plan financier : dettes, déménagement, épargne
A3: Comment l'utiliser
A4: 1. Onglet Budget : saisissez vos revenus, charges fixes (hors crédits), dépenses variables et paramètres.
A5: 2. Onglet Crédits : une ligne par crédit (capital restant dû, TAEG, mensualité, durée restante).
A6: 3. Onglet Synthèse : lisez le résultat (marge, dates clés, intérêts économisés, graphique).
A7: 4. Onglet Plan : le détail mois par mois. Calcul = moteur de simulation, ne pas modifier.
A9: Légende
A10: Cellules jaunes / texte bleu = à remplir. Texte noir = formules, ne pas écraser.
A11: Les valeurs pré-remplies sont des EXEMPLES : remplacez-les par vos chiffres.
A13: Logique du plan (ordre de priorité chaque mois)
A14: 1. Mensualités normales de tous les crédits.
A15: 2. Épargne déménagement jusqu'à l'objectif, tant que la date limite n'est pas passée.
... A29: Suivi réel : chaque fin de mois, saisissez vos soldes réels pour comparer avec le plan.

Sheet Synthèse
A1: Synthèse du plan | E1: Graphe 1 : la ligne rouge doit descendre à 0, la violette monter. Graphe 2 : les lignes pleines doivent atteindre leurs pointillés.
A3: SITUATION ACTUELLE
A4: Revenus mensuels | B4: =Budget!B7 -> 2900
A5: Charges fixes + dépenses variables | B5: =Budget!B18+Budget!B25 -> 1725
A6: Mensualités de crédit | B6: =Crédits!E11 -> 731.45
A7: Marge mensuelle disponible | B7: =B4-B5-B6 -> 443.55 | C7: Ce qui reste chaque mois pour épargner / rembourser
A8: Taux d'endettement | B8: =IFERROR(B6/B4,0) -> 0.25222414 | C8: Repère bancaire : 35 % max
A9: Alerte endettement | B9: =IF(B8>0.35,"Au-dessus de 35 %",IF(B8>0.3,"Proche du seuil","OK")) -> OK
A10: Total restant dû | B10: =Crédits!C11 -> 16400
A11: TAEG moyen pondéré | B11: =Crédits!D11 -> 0.060106707
A13: OBJECTIF DÉMÉNAGEMENT
A14: Objectif | B14: =Budget!B29 -> 4000
A15: Épargne mensuelle nécessaire (approx.) | B15: =IFERROR(MAX(0,Budget!B29-Budget!B31)/MAX(1,DATEDIF(Budget!B28,Budget!B30,"m")+1),0) -> 583.33333 | C15: Montant restant / nombre de mois jusqu'à la date limite
A16: Montant atteint à la date limite | B16: {=IFERROR(INDEX(Plan!H5:H304,MATCH(Budget!B30,Plan!B5:B304,1)),Budget!B31)} -> 3511.3
A17: Objectif atteint le | B17: {=IFERROR(INDEX(Plan!B5:B304,MATCH(1,Plan!R5:R304,0)),"Non atteint")} -> Non atteint
A18: Statut | B18: =IF(B16>=B14,"Objectif tenu","Objectif NON tenu : réduire dépenses ou décaler la date") -> Objectif NON tenu : réduire dépenses ou décaler la date
A20: FONDS D'URGENCE
A21: Cible | B21: =Budget!B32 -> 4000
A22: Cible atteinte le | B22: {=IFERROR(INDEX(Plan!B5:B304,MATCH(1,Plan!S5:S304,0)),"Non atteint (25 ans)")} -> 46692
A24: DETTES
A25: Sans dette le (avec le plan) | B25: {=IF(Crédits!C11<=0,"Aucune dette",IFERROR(INDEX(Plan!B5:B304,MATCH(1,Plan!T5:T304,0)),"Au-delà de 25 ans"))} -> 47088
A26: Intérêts payés sans remb. anticipé | B26: =SUM(Calcul!BB3:BB302) -> 1480.9951 | C26: Estimation TAEG/12
A27: Intérêts payés avec le plan | B27: =SUM(Calcul!BA3:BA302) -> 1086.6235
A28: Intérêts économisés | B28: =B26-B27 -> 394.37161 | C28: Avant éventuelles IRA
A30: ÉPARGNE (horizon 12 mois)
A31: Épargne libre cumulée à 12 mois | B31: =Plan!O16 -> 264.52
A32: Fonds d'urgence à 12 mois | B32: =Plan!J16 -> 4000
A33: Dettes restantes à 12 mois | B33: =Plan!P16 -> 9615.07
A34: Mois avec budget négatif | B34: =COUNTIF(Plan!Q5:Q304,"Budget négatif !") -> 0 | C34: Doit être 0
A36: SUIVI RÉEL (dernier mois saisi)
A37: Dernier mois renseigné | B37: {=IF(MAX('Suivi réel'!V6:V29)=0,"Aucune saisie",INDEX('Suivi réel'!A:A,MAX('Suivi réel'!V6:V29)))} -> Aucune saisie
A38: Écart dettes (réel − prévu) | B38: {=IF(MAX('Suivi réel'!V6:V29)=0,0,INDEX('Suivi réel'!O:O,MAX('Suivi réel'!V6:V29)))} -> 0
A39: Écart épargne (réel − prévu) | B39: {=IF(MAX('Suivi réel'!V6:V29)=0,0,INDEX('Suivi réel'!R:R,MAX('Suivi réel'!V6:V29)))} -> 0
A40: Statut | B40: {=IF(MAX('Suivi réel'!V6:V29)=0,"—",INDEX('Suivi réel'!U:U,MAX('Suivi réel'!V6:V29)))} -> —

Sheet Budget
A1: Budget mensuel & paramètres
A3: REVENUS NETS MENSUELS
A4: Salaire net (après impôt à la source) | B4: 2800 | C4: Valeurs d'exemple : remplacez par vos chiffres
A5: Primes / 13e mois (lissés par mois) | B5: 0
A6: Autres revenus | B6: 100
A7: Total revenus | B7: =SUM(B4:B6) -> 2900
A9: CHARGES FIXES (hors mensualités de crédit)
A10: Loyer | B10: 850
A11: Charges / énergie | B11: 60
A12: Assurances (habitation, santé...) | B12: 35
A13: Internet / mobile | B13: 30
A14: Transport (Navigo, carburant...) | B14: 75
A15: Abonnements (streaming, sport...) | B15: 25
A16: Impôts / taxes mensualisés | B16: 0
A17: Autres charges fixes | B17: 0
A18: Total charges fixes | B18: =SUM(B10:B17) -> 1075
A20: DÉPENSES VARIABLES (moyenne sur 3 mois)
A21: Courses | B21: 350
A22: Loisirs / sorties / restaurants | B22: 150
A23: Shopping | B23: 100
A24: Divers | B24: 50
A25: Total dépenses variables | B25: =SUM(B21:B24) -> 650
A27: PARAMÈTRES DU PLAN
A28: Date de début du plan | B28: 46388 | C28: 1er mois simulé
A29: Objectif épargne déménagement | B29: 4000 | C29: Montant à réunir
A30: Date limite déménagement | B30: 46568 | C30: Plus d'épargne déménagement après cette date
A31: Déjà épargné pour le déménagement | B31: 500 | C31: Montant de départ
A32: Fonds d'urgence cible | B32: 4000 | C32: Conseil : 3 mois de dépenses (voir ligne 33)
A33: Suggestion : 3 mois de dépenses | B33: =3*(B18+B25+Crédits!E11) -> 7369.35 | C33: Charges + variables + mensualités, x3
A34: Épargne de précaution déjà disponible | B34: 800 | C34: Montant de départ du fonds d'urgence
A35: Taux seuil (épargne sans risque) | B35: 0.024 | C35: EXEMPLE : mettez le taux actuel du Livret A. Crédit au TAEG supérieur = remb. anticipé rentable
A36: % du reste affecté au remb. anticipé | B36: 0.6 | C36: Le reste va en épargne libre (0 % = aucun remb. anticipé)

Sheet Crédits
A1: Mes crédits
A2: Remplissez une ligne par crédit (jaune). Laissez vides les lignes inutilisées. Valeurs d'exemple à remplacer.
A4: Nom du crédit | B4: Type | C4: Capital restant dû | D4: TAEG | E4: Mensualité | F4: Durée restante (mois) | G4: Coût total restant | H4: Intérêts restants estimés | I4: Date de fin prévue | J4: Remb. anticipé rentable ? | K4: Priorité remb. anticipé | L4: Conseil
A5: Prêt auto | B5: Prêt affecté | C5: 8200 | D5: 0.049 | E5: 245.3 | G5: =IF(C5="","",E5*F5) -> 0 | H5: =IF(C5="","",MAX(0,E5*F5-C5)) -> 0 | I5: =IF(OR(C5="",F5=""),"",EDATE(Budget!$B$28,F5)) | J5: =IF(N(C5)<=0,"",IF(N(D5)>Budget!$B$35,"Oui","Non")) -> Oui | K5: =IF(J5="Oui",COUNTIFS($J$5:$J$10,"Oui",$D$5:$D$10,">"&D5)+COUNTIFS($J$4:J4,"Oui",$D$4:D4,D5)+1,"") -> 3 | L5: =IF(N(C5)<=0,"",IF(N(D5)>=0.1,"Taux élevé : à solder en priorité",IF(J5="Oui","Remb. anticipé intéressant (vérifier IRA)","Garder, épargner plutôt"))) -> Remb. anticipé intéressant (vérifier IRA)
A6: Carte revolving | B6: Revolving | C6: 1850 | D6: 0.189 | E6: 72.4 | G6: =IF(C6="","",E6*F6) -> 0 | H6: =IF(C6="","",MAX(0,E6*F6-C6)) -> 0 | I6: =IF(OR(C6="",F6=""),"",EDATE(Budget!$B$28,F6)) | J6: =IF(N(C6)<=0,"",IF(N(D6)>Budget!$B$35,"Oui","Non")) -> Oui | K6: =IF(J6="Oui",COUNTIFS($J$5:$J$10,"Oui",$D$5:$D$10,">"&D6)+COUNTIFS($J$4:J5,"Oui",$D$4:D5,D6)+1,"") -> 1 | L6: =IF(N(C6)<=0,"",IF(N(D6)>=0.1,"Taux élevé : à solder en priorité",IF(J6="Oui","Remb. anticipé intéressant (vérifier IRA)","Garder, épargner plutôt"))) -> Taux élevé : à solder en priorité
A7: Prêt travaux | B7: Prêt personnel | C7: 3400 | D7: 0.0615 | E7: 118.75 | G7: =IF(C7="","",E7*F7) -> 0 | H7: =IF(C7="","",MAX(0,E7*F7-C7)) -> 0 | I7: =IF(OR(C7="",F7=""),"",EDATE(Budget!$B$28,F7)) | J7: =IF(N(C7)<=0,"",IF(N(D7)>Budget!$B$35,"Oui","Non")) -> Oui | K7: =IF(J7="Oui",COUNTIFS($J$5:$J$10,"Oui",$D$5:$D$10,">"&D7)+COUNTIFS($J$4:J6,"Oui",$D$4:D6,D7)+1,"") -> 2 | L7: =IF(N(C7)<=0,"",IF(N(D7)>=0.1,"Taux élevé : à solder en priorité",IF(J7="Oui","Remb. anticipé intéressant (vérifier IRA)","Garder, épargner plutôt"))) -> Remb. anticipé intéressant (vérifier IRA)
A8: Prêt étudiant | B8: Prêt étudiant | C8: 2100 | D8: 0.012 | E8: 95 | G8: =IF(C8="","",E8*F8) -> 0 | H8: =IF(C8="","",MAX(0,E8*F8-C8)) -> 0 | I8: =IF(OR(C8="",F8=""),"",EDATE(Budget!$B$28,F8)) | J8: =IF(N(C8)<=0,"",IF(N(D8)>Budget!$B$35,"Oui","Non")) -> Non | K8: =IF(J8="Oui",COUNTIFS($J$5:$J$10,"Oui",$D$5:$D$10,">"&D8)+COUNTIFS($J$4:J7,"Oui",$D$4:D7,D8)+1,"") | L8: =IF(N(C8)<=0,"",IF(N(D8)>=0.1,"Taux élevé : à solder en priorité",IF(J8="Oui","Remb. anticipé intéressant (vérifier IRA)","Garder, épargner plutôt"))) -> Garder, épargner plutôt
A9: Dette perso A | B9: Dette personnelle | C9: 600 | D9: 0 | E9: 150 | G9: =IF(C9="","",E9*F9) -> 0 | H9: =IF(C9="","",MAX(0,E9*F9-C9)) -> 0 | I9: =IF(OR(C9="",F9=""),"",EDATE(Budget!$B$28,F9)) | J9: =IF(N(C9)<=0,"",IF(N(D9)>Budget!$B$35,"Oui","Non")) -> Non | K9: =IF(J9="Oui",COUNTIFS($J$5:$J$10,"Oui",$D$5:$D$10,">"&D9)+COUNTIFS($J$4:J8,"Oui",$D$4:D8,D9)+1,"") | L9: =IF(N(C9)<=0,"",IF(N(D9)>=0.1,"Taux élevé : à solder en priorité",IF(J9="Oui","Remb. anticipé intéressant (vérifier IRA)","Garder, épargner plutôt"))) -> Garder, épargner plutôt
A10: Dette perso B | B10: Dette personnelle | C10: 250 | D10: 0 | E10: 50 | G10: =IF(C10="","",E10*F10) -> 0 | H10: =IF(C10="","",MAX(0,E10*F10-C10)) -> 0 | I10: =IF(OR(C10="",F10=""),"",EDATE(Budget!$B$28,F10)) | J10: =IF(N(C10)<=0,"",IF(N(D10)>Budget!$B$35,"Oui","Non")) -> Non | K10: =IF(J10="Oui",COUNTIFS($J$5:$J$10,"Oui",$D$5:$D$10,">"&D10)+COUNTIFS($J$4:J9,"Oui",$D$4:D9,D10)+1,"") | L10: =IF(N(C10)<=0,"",IF(N(D10)>=0.1,"Taux élevé : à solder en priorité",IF(J10="Oui","Remb. anticipé intéressant (vérifier IRA)","Garder, épargner plutôt"))) -> Garder, épargner plutôt
A11: TOTAL | C11: =SUM(C5:C10) -> 16400 | D11: =IFERROR(SUMPRODUCT(C5:C10,D5:D10)/C11,0) -> 0.060106707 | E11: =SUM(E5:E10) -> 731.45 | G11: =SUM(G5:G10) -> 0 | H11: =SUM(H5:H10) -> 0
A13: TAEG : taux annuel effectif global, indiqué sur l'offre de prêt ou le relevé annuel.
A14: Priorité 1 = crédit à rembourser par anticipation en premier (TAEG le plus élevé, au-dessus du taux seuil).

Sheet Suivi réel
A1: État des lieux : ma progression réelle
A2: Chaque début de mois, relevez vos soldes réels (banque) et remplissez les cellules JAUNES de la ligne du mois. Le reste se calcule et se compare au Plan.
A4: MOIS | B4: BUDGET RÉEL DU MOIS | D4: SOLDES D'ÉPARGNE RÉELS (fin de mois) | G4: CAPITAL RESTANT DÛ RÉEL (relevé banque) | M4: COMPARAISON AVEC LE PLAN (automatique) | X4: COMMENT FAIRE CHAQUE MOIS
A5: Mois | B5: Revenus réels | C5: Dépenses réelles (hors crédits) | D5: Épargne déménagement | E5: Fonds d'urgence | F5: Épargne libre | G5: =IF(Crédits!A5="","Crédit 1",Crédits!A5) -> Prêt auto | H5: =IF(Crédits!A6="","Crédit 2",Crédits!A6) -> Carte revolving | I5: =IF(Crédits!A7="","Crédit 3",Crédits!A7) -> Prêt travaux | J5: =IF(Crédits!A8="","Crédit 4",Crédits!A8) -> Prêt étudiant | K5: =IF(Crédits!A9="","Crédit 5",Crédits!A9) -> Dette perso A | L5: =IF(Crédits!A10="","Crédit 6",Crédits!A10) -> Dette perso B | M5: Dettes réelles | N5: Dettes prévues | O5: Écart dettes | P5: Épargne réelle totale | Q5: Épargne prévue totale | R5: Écart épargne | S5: % objectif déménag. | T5: % dettes remboursées | U5: Statut | X5: 1. Ouvrez vos comptes en fin de mois.
A6: =Plan!B5 -> 46388 | M6: =IF(COUNT(B6:L6)>0,SUM(G6:L6),"") | N6: =IF(COUNT(B6:L6)>0,Plan!P5,"") | O6: =IF(COUNT(B6:L6)>0,M6-N6,"") | P6: =IF(COUNT(B6:L6)>0,SUM(D6:F6),"") | Q6: =IF(COUNT(B6:L6)>0,Plan!H5+Plan!J5+Plan!O5,"") | R6: =IF(COUNT(B6:L6)>0,P6-Q6,"") | S6: =IF(COUNT(B6:L6)>0,IFERROR(MIN(1,D6/Budget!$B$29),0),"") | T6: =IF(COUNT(B6:L6)>0,IFERROR(MAX(0,1-M6/Crédits!$C$11),0),"") | U6: =IF(COUNT(B6:L6)>0,IF(AND(O6<=10,R6>=-10),"✅ Dans les temps",IF(AND(O6>10,R6<-10),"🔴 En retard","🟠 Mitigé")),"") | V6: =IF(COUNT(B6:L6)>0,ROW(),0) -> 0 | X6: 2. Remplissez la ligne du mois (cellules jaunes).
A7: =Plan!B6 -> 46419 | M7: =IF(COUNT(B7:L7)>0,SUM(G7:L7),"") | N7: =IF(COUNT(B7:L7)>0,Plan!P6,"") | O7: =IF(COUNT(B7:L7)>0,M7-N7,"") | P7: =IF(COUNT(B7:L7)>0,SUM(D7:F7),"") | Q7: =IF(COUNT(B7:L7)>0,Plan!H6+Plan!J6+Plan!O6,"") | R7: =IF(COUNT(B7:L7)>0,P7-Q7,"") | S7: =IF(COUNT(B7:L7)>0,IFERROR(MIN(1,D7/Budget!$B$29),0),"") | T7: =IF(COUNT(B7:L7)>0,IFERROR(MAX(0,1-M7/Crédits!$C$11),0),"") | U7: =IF(COUNT(B7:L7)>0,IF(AND(O7<=10,R7>=-10),"✅ Dans les temps",IF(AND(O7>10,R7<-10),"🔴 En retard","🟠 Mitigé")),"") | V7: =IF(COUNT(B7:L7)>0,ROW(),0) -> 0 | X7: 3. Lisez l'écart et le statut.
A8: =Plan!B7 -> 46447 | M8: =IF(COUNT(B8:L8)>0,SUM(G8:L8),"") | N8: =IF(COUNT(B8:L8)>0,Plan!P7,"") | O8: =IF(COUNT(B8:L8)>0,M8-N8,"") | P8: =IF(COUNT(B8:L8)>0,SUM(D8:F8),"") | Q8: =IF(COUNT(B8:L8)>0,Plan!H7+Plan!J7+Plan!O7,"") | R8: =IF(COUNT(B8:L8)>0,P8-Q8,"") | S8: =IF(COUNT(B8:L8)>0,IFERROR(MIN(1,D8/Budget!$B$29),0),"") | T8: =IF(COUNT(B8:L8)>0,IFERROR(MAX(0,1-M8/Crédits!$C$11),0),"") | U8: =IF(COUNT(B8:L8)>0,IF(AND(O8<=10,R8>=-10),"✅ Dans les temps",IF(AND(O8>10,R8<-10),"🔴 En retard","🟠 Mitigé")),"") | V8: =IF(COUNT(B8:L8)>0,ROW(),0) -> 0
A9: =Plan!B8 -> 46478 | M9: =IF(COUNT(B9:L9)>0,SUM(G9:L9),"") | N9: =IF(COUNT(B9:L9)>0,Plan!P8,"") | O9: =IF(COUNT(B9:L9)>0,M9-N9,"") | P9: =IF(COUNT(B9:L9)>0,SUM(D9:F9),"") | Q9: =IF(COUNT(B9:L9)>0,Plan!H8+Plan!J8+Plan!O8,"") | R9: =IF(COUNT(B9:L9)>0,P9-Q9,"") | S9: =IF(COUNT(B9:L9)>0,IFERROR(MIN(1,D9/Budget!$B$29),0),"") | T9: =IF(COUNT(B9:L9)>0,IFERROR(MAX(0,1-M9/Crédits!$C$11),0),"") | U9: =IF(COUNT(B9:L9)>0,IF(AND(O9<=10,R9>=-10),"✅ Dans les temps",IF(AND(O9>10,R9<-10),"🔴 En retard","🟠 Mitigé")),"") | V9: =IF(COUNT(B9:L9)>0,ROW(),0) -> 0 | X9: Écart dettes : vert si ≤ prévu.
A10: =Plan!B9 -> 46508 | M10: =IF(COUNT(B10:L10)>0,SUM(G10:L10),"") | N10: =IF(COUNT(B10:L10)>0,Plan!P9,"") | O10: =IF(COUNT(B10:L10)>0,M10-N10,"") | P10: =IF(COUNT(B10:L10)>0,SUM(D10:F10),"") | Q10: =IF(COUNT(B10:L10)>0,Plan!H9+Plan!J9+Plan!O9,"") | R10: =IF(COUNT(B10:L10)>0,P10-Q10,"") | S10: =IF(COUNT(B10:L10)>0,IFERROR(MIN(1,D10/Budget!$B$29),0),"") | T10: =IF(COUNT(B10:L10)>0,IFERROR(MAX(0,1-M10/Crédits!$C$11),0),"") | U10: =IF(COUNT(B10:L10)>0,IF(AND(O10<=10,R10>=-10),"✅ Dans les temps",IF(AND(O10>10,R10<-10),"🔴 En retard","🟠 Mitigé")),"") | V10: =IF(COUNT(B10:L10)>0,ROW(),0) -> 0 | X10: Écart épargne : vert si ≥ prévu.
A11: =Plan!B10 -> 46539 | M11: =IF(COUNT(B11:L11)>0,SUM(G11:L11),"") | N11: =IF(COUNT(B11:L11)>0,Plan!P10,"") | O11: =IF(COUNT(B11:L11)>0,M11-N11,"") | P11: =IF(COUNT(B11:L11)>0,SUM(D11:F11),"") | Q11: =IF(COUNT(B11:L11)>0,Plan!H10+Plan!J10+Plan!O10,"") | R11: =IF(COUNT(B11:L11)>0,P11-Q11,"") | S11: =IF(COUNT(B11:L11)>0,IFERROR(MIN(1,D11/Budget!$B$29),0),"") | T11: =IF(COUNT(B11:L11)>0,IFERROR(MAX(0,1-M11/Crédits!$C$11),0),"") | U11: =IF(COUNT(B11:L11)>0,IF(AND(O11<=10,R11>=-10),"✅ Dans les temps",IF(AND(O11>10,R11<-10),"🔴 En retard","🟠 Mitigé")),"") | V11: =IF(COUNT(B11:L11)>0,ROW(),0) -> 0 | X11: Mois en cours surligné en jaune.
A12: =Plan!B11 -> 46569 | M12: =IF(COUNT(B12:L12)>0,SUM(G12:L12),"") | N12: =IF(COUNT(B12:L12)>0,Plan!P11,"") | O12: =IF(COUNT(B12:L12)>0,M12-N12,"") | P12: =IF(COUNT(B12:L12)>0,SUM(D12:F12),"") | Q12: =IF(COUNT(B12:L12)>0,Plan!H11+Plan!J11+Plan!O11,"") | R12: =IF(COUNT(B12:L12)>0,P12-Q12,"") | S12: =IF(COUNT(B12:L12)>0,IFERROR(MIN(1,D12/Budget!$B$29),0),"") | T12: =IF(COUNT(B12:L12)>0,IFERROR(MAX(0,1-M12/Crédits!$C$11),0),"") | U12: =IF(COUNT(B12:L12)>0,IF(AND(O12<=10,R12>=-10),"✅ Dans les temps",IF(AND(O12>10,R12<-10),"🔴 En retard","🟠 Mitigé")),"") | V12: =IF(COUNT(B12:L12)>0,ROW(),0) -> 0 | X12: Une colonne vide = laissez vide.
A13: =Plan!B12 -> 46600 | M13: =IF(COUNT(B13:L13)>0,SUM(G13:L13),"") | N13: =IF(COUNT(B13:L13)>0,Plan!P12,"") | O13: =IF(COUNT(B13:L13)>0,M13-N13,"") | P13: =IF(COUNT(B13:L13)>0,SUM(D13:F13),"") | Q13: =IF(COUNT(B13:L13)>0,Plan!H12+Plan!J12+Plan!O12,"") | R13: =IF(COUNT(B13:L13)>0,P13-Q13,"") | S13: =IF(COUNT(B13:L13)>0,IFERROR(MIN(1,D13/Budget!$B$29),0),"") | T13: =IF(COUNT(B13:L13)>0,IFERROR(MAX(0,1-M13/Crédits!$C$11),0),"") | U13: =IF(COUNT(B13:L13)>0,IF(AND(O13<=10,R13>=-10),"✅ Dans les temps",IF(AND(O13>10,R13<-10),"🔴 En retard","🟠 Mitigé")),"") | V13: =IF(COUNT(B13:L13)>0,ROW(),0) -> 0
A14: =Plan!B13 -> 46631 | M14: =IF(COUNT(B14:L14)>0,SUM(G14:L14),"") | N14: =IF(COUNT(B14:L14)>0,Plan!P13,"") | O14: =IF(COUNT(B14:L14)>0,M14-N14,"") | P14: =IF(COUNT(B14:L14)>0,SUM(D14:F14),"") | Q14: =IF(COUNT(B14:L14)>0,Plan!H13+Plan!J13+Plan!O13,"") | R14: =IF(COUNT(B14:L14)>0,P14-Q14,"") | S14: =IF(COUNT(B14:L14)>0,IFERROR(MIN(1,D14/Budget!$B$29),0),"") | T14: =IF(COUNT(B14:L14)>0,IFERROR(MAX(0,1-M14/Crédits!$C$11),0),"") | U14: =IF(COUNT(B14:L14)>0,IF(AND(O14<=10,R14>=-10),"✅ Dans les temps",IF(AND(O14>10,R14<-10),"🔴 En retard","🟠 Mitigé")),"") | V14: =IF(COUNT(B14:L14)>0,ROW(),0) -> 0 | X14: Si vous prenez du retard, ajustez
A15: =Plan!B14 -> 46661 | M15: =IF(COUNT(B15:L15)>0,SUM(G15:L15),"") | N15: =IF(COUNT(B15:L15)>0,Plan!P14,"") | O15: =IF(COUNT(B15:L15)>0,M15-N15,"") | P15: =IF(COUNT(B15:L15)>0,SUM(D15:F15),"") | Q15: =IF(COUNT(B15:L15)>0,Plan!H14+Plan!J14+Plan!O14,"") | R15: =IF(COUNT(B15:L15)>0,P15-Q15,"") | S15: =IF(COUNT(B15:L15)>0,IFERROR(MIN(1,D15/Budget!$B$29),0),"") | T15: =IF(COUNT(B15:L15)>0,IFERROR(MAX(0,1-M15/Crédits!$C$11),0),"") | U15: =IF(COUNT(B15:L15)>0,IF(AND(O15<=10,R15>=-10),"✅ Dans les temps",IF(AND(O15>10,R15<-10),"🔴 En retard","🟠 Mitigé")),"") | V15: =IF(COUNT(B15:L15)>0,ROW(),0) -> 0 | X15: Budget (dépenses) pour recalculer.
A16: =Plan!B15 -> 46692 | M16: =IF(COUNT(B16:L16)>0,SUM(G16:L16),"") | N16: =IF(COUNT(B16:L16)>0,Plan!P15,"") | O16: =IF(COUNT(B16:L16)>0,M16-N16,"") | P16: =IF(COUNT(B16:L16)>0,SUM(D16:F16),"") | Q16: =IF(COUNT(B16:L16)>0,Plan!H15+Plan!J15+Plan!O15,"") | R16: =IF(COUNT(B16:L16)>0,P16-Q16,"") | S16: =IF(COUNT(B16:L16)>0,IFERROR(MIN(1,D16/Budget!$B$29),0),"") | T16: =IF(COUNT(B16:L16)>0,IFERROR(MAX(0,1-M16/Crédits!$C$11),0),"") | U16: =IF(COUNT(B16:L16)>0,IF(AND(O16<=10,R16>=-10),"✅ Dans les temps",IF(AND(O16>10,R16<-10),"🔴 En retard","🟠 Mitigé")),"") | V16: =IF(COUNT(B16:L16)>0,ROW(),0) -> 0
A17: =Plan!B16 -> 46722 | M17: =IF(COUNT(B17:L17)>0,SUM(G17:L17),"") | N17: =IF(COUNT(B17:L17)>0,Plan!P16,"") | O17: =IF(COUNT(B17:L17)>0,M17-N17,"") | P17: =IF(COUNT(B17:L17)>0,SUM(D17:F17),"") | Q17: =IF(COUNT(B17:L17)>0,Plan!H16+Plan!J16+Plan!O16,"") | R17: =IF(COUNT(B17:L17)>0,P17-Q17,"") | S17: =IF(COUNT(B17:L17)>0,IFERROR(MIN(1,D17/Budget!$B$29),0),"") | T17: =IF(COUNT(B17:L17)>0,IFERROR(MAX(0,1-M17/Crédits!$C$11),0),"") | U17: =IF(COUNT(B17:L17)>0,IF(AND(O17<=10,R17>=-10),"✅ Dans les temps",IF(AND(O17>10,R17<-10),"🔴 En retard","🟠 Mitigé")),"") | V17: =IF(COUNT(B17:L17)>0,ROW(),0) -> 0
A18: =Plan!B17 -> 46753 | M18: =IF(COUNT(B18:L18)>0,SUM(G18:L18),"") | N18: =IF(COUNT(B18:L18)>0,Plan!P17,"") | O18: =IF(COUNT(B18:L18)>0,M18-N18,"") | P18: =IF(COUNT(B18:L18)>0,SUM(D18:F18),"") | Q18: =IF(COUNT(B18:L18)>0,Plan!H17+Plan!J17+Plan!O17,"") | R18: =IF(COUNT(B18:L18)>0,P18-Q18,"") | S18: =IF(COUNT(B18:L18)>0,IFERROR(MIN(1,D18/Budget!$B$29),0),"") | T18: =IF(COUNT(B18:L18)>0,IFERROR(MAX(0,1-M18/Crédits!$C$11),0),"") | U18: =IF(COUNT(B18:L18)>0,IF(AND(O18<=10,R18>=-10),"✅ Dans les temps",IF(AND(O18>10,R18<-10),"🔴 En retard","🟠 Mitigé")),"") | V18: =IF(COUNT(B18:L18)>0,ROW(),0) -> 0
A19: =Plan!B18 -> 46784 | M19: =IF(COUNT(B19:L19)>0,SUM(G19:L19),"") | N19: =IF(COUNT(B19:L19)>0,Plan!P18,"") | O19: =IF(COUNT(B19:L19)>0,M19-N19,"") | P19: =IF(COUNT(B19:L19)>0,SUM(D19:F19),"") | Q19: =IF(COUNT(B19:L19)>0,Plan!H18+Plan!J18+Plan!O18,"") | R19: =IF(COUNT(B19:L19)>0,P19-Q19,"") | S19: =IF(COUNT(B19:L19)>0,IFERROR(MIN(1,D19/Budget!$B$29),0),"") | T19: =IF(COUNT(B19:L19)>0,IFERROR(MAX(0,1-M19/Crédits!$C$11),0),"") | U19: =IF(COUNT(B19:L19)>0,IF(AND(O19<=10,R19>=-10),"✅ Dans les temps",IF(AND(O19>10,R19<-10),"🔴 En retard","🟠 Mitigé")),"") | V19: =IF(COUNT(B19:L19)>0,ROW(),0) -> 0
A20: =Plan!B19 -> 46813 | M20: =IF(COUNT(B20:L20)>0,SUM(G20:L20),"") | N20: =IF(COUNT(B20:L20)>0,Plan!P19,"") | O20: =IF(COUNT(B20:L20)>0,M20-N20,"") | P20: =IF(COUNT(B20:L20)>0,SUM(D20:F20),"") | Q20: =IF(COUNT(B20:L20)>0,Plan!H19+Plan!J19+Plan!O19,"") | R20: =IF(COUNT(B20:L20)>0,P20-Q20,"") | S20: =IF(COUNT(B20:L20)>0,IFERROR(MIN(1,D20/Budget!$B$29),0),"") | T20: =IF(COUNT(B20:L20)>0,IFERROR(MAX(0,1-M20/Crédits!$C$11),0),"") | U20: =IF(COUNT(B20:L20)>0,IF(AND(O20<=10,R20>=-10),"✅ Dans les temps",IF(AND(O20>10,R20<-10),"🔴 En retard","🟠 Mitigé")),"") | V20: =IF(COUNT(B20:L20)>0,ROW(),0) -> 0
A21: =Plan!B20 -> 46844 | M21: =IF(COUNT(B21:L21)>0,SUM(G21:L21),"") | N21: =IF(COUNT(B21:L21)>0,Plan!P20,"") | O21: =IF(COUNT(B21:L21)>0,M21-N21,"") | P21: =IF(COUNT(B21:L21)>0,SUM(D21:F21),"") | Q21: =IF(COUNT(B21:L21)>0,Plan!H20+Plan!J20+Plan!O20,"") | R21: =IF(COUNT(B21:L21)>0,P21-Q21,"") | S21: =IF(COUNT(B21:L21)>0,IFERROR(MIN(1,D21/Budget!$B$29),0),"") | T21: =IF(COUNT(B21:L21)>0,IFERROR(MAX(0,1-M21/Crédits!$C$11),0),"") | U21: =IF(COUNT(B21:L21)>0,IF(AND(O21<=10,R21>=-10),"✅ Dans les temps",IF(AND(O21>10,R21<-10),"🔴 En retard","🟠 Mitigé")),"") | V21: =IF(COUNT(B21:L21)>0,ROW(),0) -> 0
A22: =Plan!B21 -> 46874 | M22: =IF(COUNT(B22:L22)>0,SUM(G22:L22),"") | N22: =IF(COUNT(B22:L22)>0,Plan!P21,"") | O22: =IF(COUNT(B22:L22)>0,M22-N22,"") | P22: =IF(COUNT(B22:L22)>0,SUM(D22:F22),"") | Q22: =IF(COUNT(B22:L22)>0,Plan!H21+Plan!J21+Plan!O21,"") | R22: =IF(COUNT(B22:L22)>0,P22-Q22,"") | S22: =IF(COUNT(B22:L22)>0,IFERROR(MIN(1,D22/Budget!$B$29),0),"") | T22: =IF(COUNT(B22:L22)>0,IFERROR(MAX(0,1-M22/Crédits!$C$11),0),"") | U22: =IF(COUNT(B22:L22)>0,IF(AND(O22<=10,R22>=-10),"✅ Dans les temps",IF(AND(O22>10,R22<-10),"🔴 En retard","🟠 Mitigé")),"") | V22: =IF(COUNT(B22:L22)>0,ROW(),0) -> 0
A23: =Plan!B22 -> 46905 | M23: =IF(COUNT(B23:L23)>0,SUM(G23:L23),"") | N23: =IF(COUNT(B23:L23)>0,Plan!P22,"") | O23: =IF(COUNT(B23:L23)>0,M23-N23,"") | P23: =IF(COUNT(B23:L23)>0,SUM(D23:F23),"") | Q23: =IF(COUNT(B23:L23)>0,Plan!H22+Plan!J22+Plan!O22,"") | R23: =IF(COUNT(B23:L23)>0,P23-Q23,"") | S23: =IF(COUNT(B23:L23)>0,IFERROR(MIN(1,D23/Budget!$B$29),0),"") | T23: =IF(COUNT(B23:L23)>0,IFERROR(MAX(0,1-M23/Crédits!$C$11),0),"") | U23: =IF(COUNT(B23:L23)>0,IF(AND(O23<=10,R23>=-10),"✅ Dans les temps",IF(AND(O23>10,R23<-10),"🔴 En retard","🟠 Mitigé")),"") | V23: =IF(COUNT(B23:L23)>0,ROW(),0) -> 0
A24: =Plan!B23 -> 46935 | M24: =IF(COUNT(B24:L24)>0,SUM(G24:L24),"") | N24: =IF(COUNT(B24:L24)>0,Plan!P23,"") | O24: =IF(COUNT(B24:L24)>0,M24-N24,"") | P24: =IF(COUNT(B24:L24)>0,SUM(D24:F24),"") | Q24: =IF(COUNT(B24:L24)>0,Plan!H23+Plan!J23+Plan!O23,"") | R24: =IF(COUNT(B24:L24)>0,P24-Q24,"") | S24: =IF(COUNT(B24:L24)>0,IFERROR(MIN(1,D24/Budget!$B$29),0),"") | T24: =IF(COUNT(B24:L24)>0,IFERROR(MAX(0,1-M24/Crédits!$C$11),0),"") | U24: =IF(COUNT(B24:L24)>0,IF(AND(O24<=10,R24>=-10),"✅ Dans les temps",IF(AND(O24>10,R24<-10),"🔴 En retard","🟠 Mitigé")),"") | V24: =IF(COUNT(B24:L24)>0,ROW(),0) -> 0
A25: =Plan!B24 -> 46966 | M25: =IF(COUNT(B25:L25)>0,SUM(G25:L25),"") | N25: =IF(COUNT(B25:L25)>0,Plan!P24,"") | O25: =IF(COUNT(B25:L25)>0,M25-N25,"") | P25: =IF(COUNT(B25:L25)>0,SUM(D25:F25),"") | Q25: =IF(COUNT(B25:L25)>0,Plan!H24+Plan!J24+Plan!O24,"") | R25: =IF(COUNT(B25:L25)>0,P25-Q25,"") | S25: =IF(COUNT(B25:L25)>0,IFERROR(MIN(1,D25/Budget!$B$29),0),"") | T25: =IF(COUNT(B25:L25)>0,IFERROR(MAX(0,1-M25/Crédits!$C$11),0),"") | U25: =IF(COUNT(B25:L25)>0,IF(AND(O25<=10,R25>=-10),"✅ Dans les temps",IF(AND(O25>10,R25<-10),"🔴 En retard","🟠 Mitigé")),"") | V25: =IF(COUNT(B25:L25)>0,ROW(),0) -> 0
A26: =Plan!B25 -> 46997 | M26: =IF(COUNT(B26:L26)>0,SUM(G26:L26),"") | N26: =IF(COUNT(B26:L26)>0,Plan!P25,"") | O26: =IF(COUNT(B26:L26)>0,M26-N26,"") | P26: =IF(COUNT(B26:L26)>0,SUM(D26:F26),"") | Q26: =IF(COUNT(B26:L26)>0,Plan!H25+Plan!J25+Plan!O25,"") | R26: =IF(COUNT(B26:L26)>0,P26-Q26,"") | S26: =IF(COUNT(B26:L26)>0,IFERROR(MIN(1,D26/Budget!$B$29),0),"") | T26: =IF(COUNT(B26:L26)>0,IFERROR(MAX(0,1-M26/Crédits!$C$11),0),"") | U26: =IF(COUNT(B26:L26)>0,IF(AND(O26<=10,R26>=-10),"✅ Dans les temps",IF(AND(O26>10,R26<-10),"🔴 En retard","🟠 Mitigé")),"") | V26: =IF(COUNT(B26:L26)>0,ROW(),0) -> 0
A27: =Plan!B26 -> 47027 | M27: =IF(COUNT(B27:L27)>0,SUM(G27:L27),"") | N27: =IF(COUNT(B27:L27)>0,Plan!P26,"") | O27: =IF(COUNT(B27:L27)>0,M27-N27,"") | P27: =IF(COUNT(B27:L27)>0,SUM(D27:F27),"") | Q27: =IF(COUNT(B27:L27)>0,Plan!H26+Plan!J26+Plan!O26,"") | R27: =IF(COUNT(B27:L27)>0,P27-Q27,"") | S27: =IF(COUNT(B27:L27)>0,IFERROR(MIN(1,D27/Budget!$B$29),0),"") | T27: =IF(COUNT(B27:L27)>0,IFERROR(MAX(0,1-M27/Crédits!$C$11),0),"") | U27: =IF(COUNT(B27:L27)>0,IF(AND(O27<=10,R27>=-10),"✅ Dans les temps",IF(AND(O27>10,R27<-10),"🔴 En retard","🟠 Mitigé")),"") | V27: =IF(COUNT(B27:L27)>0,ROW(),0) -> 0
... A29: =Plan!B28 -> 47088 | M29: =IF(COUNT(B29:L29)>0,SUM(G29:L29),"") | N29: =IF(COUNT(B29:L29)>0,Plan!P28,"") | O29: =IF(COUNT(B29:L29)>0,M29-N29,"") | P29: =IF(COUNT(B29:L29)>0,SUM(D29:F29),"") | Q29: =IF(COUNT(B29:L29)>0,Plan!H28+Plan!J28+Plan!O28,"") | R29: =IF(COUNT(B29:L29)>0,P29-Q29,"") | S29: =IF(COUNT(B29:L29)>0,IFERROR(MIN(1,D29/Budget!$B$29),0),"") | T29: =IF(COUNT(B29:L29)>0,IFERROR(MAX(0,1-M29/Crédits!$C$11),0),"") | U29: =IF(COUNT(B29:L29)>0,IF(AND(O29<=10,R29>=-10),"✅ Dans les temps",IF(AND(O29>10,R29<-10),"🔴 En retard","🟠 Mitigé")),"") | V29: =IF(COUNT(B29:L29)>0,ROW(),0) -> 0

Sheet Plan
A1: Plan mois par mois (LECTURE SEULE : rien à remplir ici)
A2: Chaque ligne = 1 mois. Lire de gauche à droite : l'argent disponible est réparti dans l'ordre 1 → 2 → 3 → 4. Pour changer le résultat, modifiez Budget ou Crédits.
A3: PÉRIODE | C3: ① ARGENT DU MOIS : revenus − dépenses − crédits = Disponible | G3: ② DÉMÉNAGEMENT | I3: ③ FONDS D'URGENCE | K3: ④ CE QUI RESTE : remb. anticipé + épargne libre | P3: DETTES | V3: COMMENT LIRE CET ONGLET
A4: Mois | B4: Date | C4: Revenus | D4: Dépenses (fixes + var.) | E4: Mensualités crédits | F4: Disponible | G4: → Déménagement | H4: Cumul déménagement | I4: → Fonds d'urgence | J4: Cumul fonds d'urgence | K4: Reste | L4: → Remb. anticipé | M4: Non utilisé (dettes soldées) | N4: → Épargne libre | O4: Cumul épargne libre | P4: Dettes restantes | Q4: Alerte | R4: flag_dem | S4: flag_fu | T4: flag_dette | V4: Rien à saisir : tout se calcule depuis Budget et Crédits. | AA4: Objectif déménagement | AB4: Cible fonds d'urgence
A5: 1 | B5: =EDATE(Budget!$B$28,A5-1) -> 46388 | C5: =Budget!$B$7 -> 2900 | D5: =Budget!$B$18+Budget!$B$25 -> 1725 | E5: =Calcul!AX3 -> 731.45 | F5: =C5-D5-E5 -> 443.55 | G5: =IF(B5<=Budget!$B$30,MAX(0,MIN(F5,Budget!$B$29-Budget!$B$31)),0) -> 443.55 | H5: =Budget!$B$31+G5 -> 943.55 | I5: =MAX(0,MIN(F5-G5,Budget!$B$32-Budget!$B$34)) -> 0 | J5: =Budget!$B$34+I5 -> 800 | K5: =MAX(0,F5-G5-I5) -> 0 | L5: =K5*Budget!$B$36 -> 0 | M5: =MAX(0,L5-Calcul!AY3) -> 0 | N5: =K5-L5+M5 -> 0 | O5: =0+N5 -> 0 | P5: =Calcul!AZ3 -> 15750.7 | Q5: =IF(F5<0,"Budget négatif !","") | R5: =IF(H5>=Budget!$B$29,1,0) -> 0 | S5: =IF(J5>=Budget!$B$32,1,0) -> 0 | T5: =IF(P5<=0.01,1,0) -> 0 | V5: Chaque mois, le Disponible (①) est réparti dans l'ordre : | AA5: =Budget!$B$29 -> 4000 | AB5: =Budget!$B$32 -> 4000
A6: 2 | B6: =EDATE(Budget!$B$28,A6-1) -> 46419 | C6: =Budget!$B$7 -> 2900 | D6: =Budget!$B$18+Budget!$B$25 -> 1725 | E6: =Calcul!AX4 -> 731.45 | F6: =C6-D6-E6 -> 443.55 | G6: =IF(B6<=Budget!$B$30,MAX(0,MIN(F6,Budget!$B$29-H5)),0) -> 443.55 | H6: =H5+G6 -> 1387.1 | I6: =MAX(0,MIN(F6-G6,Budget!$B$32-J5)) -> 0 | J6: =J5+I6 -> 800 | K6: =MAX(0,F6-G6-I6) -> 0 | L6: =K6*Budget!$B$36 -> 0 | M6: =MAX(0,L6-Calcul!AY4) -> 0 | N6: =K6-L6+M6 -> 0 | O6: =O5+N6 -> 0 | P6: =Calcul!AZ4 -> 15099.25 | Q6: =IF(F6<0,"Budget négatif !","") | R6: =IF(H6>=Budget!$B$29,1,0) -> 0 | S6: =IF(J6>=Budget!$B$32,1,0) -> 0 | T6: =IF(P6<=0.01,1,0) -> 0 | V6: ① Argent du mois | AA6: =Budget!$B$29 -> 4000 | AB6: =Budget!$B$32 -> 4000
A7: 3 | B7: =EDATE(Budget!$B$28,A7-1) -> 46447 | C7: =Budget!$B$7 -> 2900 | D7: =Budget!$B$18+Budget!$B$25 -> 1725 | E7: =Calcul!AX5 -> 731.45 | F7: =C7-D7-E7 -> 443.55 | G7: =IF(B7<=Budget!$B$30,MAX(0,MIN(F7,Budget!$B$29-H6)),0) -> 443.55 | H7: =H6+G7 -> 1830.65 | I7: =MAX(0,MIN(F7-G7,Budget!$B$32-J6)) -> 0 | J7: =J6+I7 -> 800 | K7: =MAX(0,F7-G7-I7) -> 0 | L7: =K7*Budget!$B$36 -> 0 | M7: =MAX(0,L7-Calcul!AY5) -> 0 | N7: =K7-L7+M7 -> 0 | O7: =O6+N7 -> 0 | P7: =Calcul!AZ5 -> 14445.6 | Q7: =IF(F7<0,"Budget négatif !","") | R7: =IF(H7>=Budget!$B$29,1,0) -> 0 | S7: =IF(J7>=Budget!$B$32,1,0) -> 0 | T7: =IF(P7<=0.01,1,0) -> 0 | V7: ② Déménagement, jusqu'à l'objectif | AA7: =Budget!$B$29 -> 4000 | AB7: =Budget!$B$32 -> 4000
A8: 4 | B8: =EDATE(Budget!$B$28,A8-1) -> 46478 | C8: =Budget!$B$7 -> 2900 | D8: =Budget!$B$18+Budget!$B$25 -> 1725 | E8: =Calcul!AX6 -> 731.45 | F8: =C8-D8-E8 -> 443.55 | G8: =IF(B8<=Budget!$B$30,MAX(0,MIN(F8,Budget!$B$29-H7)),0) -> 443.55 | H8: =H7+G8 -> 2274.2 | I8: =MAX(0,MIN(F8-G8,Budget!$B$32-J7)) -> 0 | J8: =J7+I8 -> 800 | K8: =MAX(0,F8-G8-I8) -> 0 | L8: =K8*Budget!$B$36 -> 0 | M8: =MAX(0,L8-Calcul!AY6) -> 0 | N8: =K8-L8+M8 -> 0 | O8: =O7+N8 -> 0 | P8: =Calcul!AZ6 -> 13789.77 | Q8: =IF(F8<0,"Budget négatif !","") | R8: =IF(H8>=Budget!$B$29,1,0) -> 0 | S8: =IF(J8>=Budget!$B$32,1,0) -> 0 | T8: =IF(P8<=0.01,1,0) -> 0 | V8: ③ Fonds d'urgence, jusqu'à la cible | AA8: =Budget!$B$29 -> 4000 | AB8: =Budget!$B$32 -> 4000
A9: 5 | B9: =EDATE(Budget!$B$28,A9-1) -> 46508 | C9: =Budget!$B$7 -> 2900 | D9: =Budget!$B$18+Budget!$B$25 -> 1725 | E9: =Calcul!AX7 -> 581.45 | F9: =C9-D9-E9 -> 593.55 | G9: =IF(B9<=Budget!$B$30,MAX(0,MIN(F9,Budget!$B$29-H8)),0) -> 593.55 | H9: =H8+G9 -> 2867.75 | I9: =MAX(0,MIN(F9-G9,Budget!$B$32-J8)) -> 0 | J9: =J8+I9 -> 800 | K9: =MAX(0,F9-G9-I9) -> 0 | L9: =K9*Budget!$B$36 -> 0 | M9: =MAX(0,L9-Calcul!AY7) -> 0 | N9: =K9-L9+M9 -> 0 | O9: =O8+N9 -> 0 | P9: =Calcul!AZ7 -> 13281.73 | Q9: =IF(F9<0,"Budget négatif !","") | R9: =IF(H9>=Budget!$B$29,1,0) -> 0 | S9: =IF(J9>=Budget!$B$32,1,0) -> 0 | T9: =IF(P9<=0.01,1,0) -> 0 | V9: ④ Remb. anticipé + épargne libre | AA9: =Budget!$B$29 -> 4000 | AB9: =Budget!$B$32 -> 4000
A10: 6 | B10: =EDATE(Budget!$B$28,A10-1) -> 46539 | C10: =Budget!$B$7 -> 2900 | D10: =Budget!$B$18+Budget!$B$25 -> 1725 | E10: =Calcul!AX8 -> 531.45 | F10: =C10-D10-E10 -> 643.55 | G10: =IF(B10<=Budget!$B$30,MAX(0,MIN(F10,Budget!$B$29-H9)),0) -> 643.55 | H10: =H9+G10 -> 3511.3 | I10: =MAX(0,MIN(F10-G10,Budget!$B$32-J9)) -> 0 | J10: =J9+I10 -> 800 | K10: =MAX(0,F10-G10-I10) -> 0 | L10: =K10*Budget!$B$36 -> 0 | M10: =MAX(0,L10-Calcul!AY8) -> 0 | N10: =K10-L10+M10 -> 0 | O10: =O9+N10 -> 0 | P10: =Calcul!AZ8 -> 12821.45 | Q10: =IF(F10<0,"Budget négatif !","") | R10: =IF(H10>=Budget!$B$29,1,0) -> 0 | S10: =IF(J10>=Budget!$B$32,1,0) -> 0 | T10: =IF(P10<=0.01,1,0) -> 0 | V10: Dettes restantes | AA10: =Budget!$B$29 -> 4000 | AB10: =Budget!$B$32 -> 4000
A11: 7 | B11: =EDATE(Budget!$B$28,A11-1) -> 46569 | C11: =Budget!$B$7 -> 2900 | D11: =Budget!$B$18+Budget!$B$25 -> 1725 | E11: =Calcul!AX9 -> 531.45 | F11: =C11-D11-E11 -> 643.55 | G11: =IF(B11<=Budget!$B$30,MAX(0,MIN(F11,Budget!$B$29-H10)),0) -> 0 | H11: =H10+G11 -> 3511.3 | I11: =MAX(0,MIN(F11-G11,Budget!$B$32-J10)) -> 643.55 | J11: =J10+I11 -> 1443.55 | K11: =MAX(0,F11-G11-I11) -> 0 | L11: =K11*Budget!$B$36 -> 0 | M11: =MAX(0,L11-Calcul!AY9) -> 0 | N11: =K11-L11+M11 -> 0 | O11: =O10+N11 -> 0 | P11: =Calcul!AZ9 -> 12358.93 | Q11: =IF(F11<0,"Budget négatif !","") | R11: =IF(H11>=Budget!$B$29,1,0) -> 0 | S11: =IF(J11>=Budget!$B$32,1,0) -> 0 | T11: =IF(P11<=0.01,1,0) -> 0 | AA11: =Budget!$B$29 -> 4000 | AB11: =Budget!$B$32 -> 4000
A12: 8 | B12: =EDATE(Budget!$B$28,A12-1) -> 46600 | C12: =Budget!$B$7 -> 2900 | D12: =Budget!$B$18+Budget!$B$25 -> 1725 | E12: =Calcul!AX10 -> 531.45 | F12: =C12-D12-E12 -> 643.55 | G12: =IF(B12<=Budget!$B$30,MAX(0,MIN(F12,Budget!$B$29-H11)),0) -> 0 | H12: =H11+G12 -> 3511.3 | I12: =MAX(0,MIN(F12-G12,Budget!$B$32-J11)) -> 643.55 | J12: =J11+I12 -> 2087.1 | K12: =MAX(0,F12-G12-I12) -> 0 | L12: =K12*Budget!$B$36 -> 0 | M12: =MAX(0,L12-Calcul!AY10) -> 0 | N12: =K12-L12+M12 -> 0 | O12: =O11+N12 -> 0 | P12: =Calcul!AZ10 -> 11894.15 | Q12: =IF(F12<0,"Budget négatif !","") | R12: =IF(H12>=Budget!$B$29,1,0) -> 0 | S12: =IF(J12>=Budget!$B$32,1,0) -> 0 | T12: =IF(P12<=0.01,1,0) -> 0 | V12: Cellule verte = objectif atteint / dette soldée | AA12: =Budget!$B$29 -> 4000 | AB12: =Budget!$B$32 -> 4000
A13: 9 | B13: =EDATE(Budget!$B$28,A13-1) -> 46631 | C13: =Budget!$B$7 -> 2900 | D13: =Budget!$B$18+Budget!$B$25 -> 1725 | E13: =Calcul!AX11 -> 531.45 | F13: =C13-D13-E13 -> 643.55 | G13: =IF(B13<=Budget!$B$30,MAX(0,MIN(F13,Budget!$B$29-H12)),0) -> 0 | H13: =H12+G13 -> 3511.3 | I13: =MAX(0,MIN(F13-G13,Budget!$B$32-J12)) -> 643.55 | J13: =J12+I13 -> 2730.65 | K13: =MAX(0,F13-G13-I13) -> 0 | L13: =K13*Budget!$B$36 -> 0 | M13: =MAX(0,L13-Calcul!AY11) -> 0 | N13: =K13-L13+M13 -> 0 | O13: =O12+N13 -> 0 | P13: =Calcul!AZ11 -> 11427.09 | Q13: =IF(F13<0,"Budget négatif !","") | R13: =IF(H13>=Budget!$B$29,1,0) -> 0 | S13: =IF(J13>=Budget!$B$32,1,0) -> 0 | T13: =IF(P13<=0.01,1,0) -> 0 | V13: Ligne rouge = budget négatif ce mois | AA13: =Budget!$B$29 -> 4000 | AB13: =Budget!$B$32 -> 4000
A14: 10 | B14: =EDATE(Budget!$B$28,A14-1) -> 46661 | C14: =Budget!$B$7 -> 2900 | D14: =Budget!$B$18+Budget!$B$25 -> 1725 | E14: =Calcul!AX12 -> 531.45 | F14: =C14-D14-E14 -> 643.55 | G14: =IF(B14<=Budget!$B$30,MAX(0,MIN(F14,Budget!$B$29-H13)),0) -> 0 | H14: =H13+G14 -> 3511.3 | I14: =MAX(0,MIN(F14-G14,Budget!$B$32-J13)) -> 643.55 | J14: =J13+I14 -> 3374.2 | K14: =MAX(0,F14-G14-I14) -> 0 | L14: =K14*Budget!$B$36 -> 0 | M14: =MAX(0,L14-Calcul!AY12) -> 0 | N14: =K14-L14+M14 -> 0 | O14: =O13+N14 -> 0 | P14: =Calcul!AZ12 -> 10957.72 | Q14: =IF(F14<0,"Budget négatif !","") | R14: =IF(H14>=Budget!$B$29,1,0) -> 0 | S14: =IF(J14>=Budget!$B$32,1,0) -> 0 | T14: =IF(P14<=0.01,1,0) -> 0 | V14: Trait orange = mois de la date limite déménagement | AA14: =Budget!$B$29 -> 4000 | AB14: =Budget!$B$32 -> 4000
A15: 11 | B15: =EDATE(Budget!$B$28,A15-1) -> 46692 | C15: =Budget!$B$7 -> 2900 | D15: =Budget!$B$18+Budget!$B$25 -> 1725 | E15: =Calcul!AX13 -> 531.45 | F15: =C15-D15-E15 -> 643.55 | G15: =IF(B15<=Budget!$B$30,MAX(0,MIN(F15,Budget!$B$29-H14)),0) -> 0 | H15: =H14+G15 -> 3511.3 | I15: =MAX(0,MIN(F15-G15,Budget!$B$32-J14)) -> 625.8 | J15: =J14+I15 -> 4000 | K15: =MAX(0,F15-G15-I15) -> 17.75 | L15: =K15*Budget!$B$36 -> 10.65 | M15: =MAX(0,L15-Calcul!AY13) -> 0 | N15: =K15-L15+M15 -> 7.1 | O15: =O14+N15 -> 7.1 | P15: =Calcul!AZ13 -> 10475.39 | Q15: =IF(F15<0,"Budget négatif !","") | R15: =IF(H15>=Budget!$B$29,1,0) -> 0 | S15: =IF(J15>=Budget!$B$32,1,0) -> 1 | T15: =IF(P15<=0.01,1,0) -> 0 | V15: Colonnes en gras = résultats clés | AA15: =Budget!$B$29 -> 4000 | AB15: =Budget!$B$32 -> 4000
A16: 12 | B16: =EDATE(Budget!$B$28,A16-1) -> 46722 | C16: =Budget!$B$7 -> 2900 | D16: =Budget!$B$18+Budget!$B$25 -> 1725 | E16: =Calcul!AX14 -> 531.45 | F16: =C16-D16-E16 -> 643.55 | G16: =IF(B16<=Budget!$B$30,MAX(0,MIN(F16,Budget!$B$29-H15)),0) -> 0 | H16: =H15+G16 -> 3511.3 | I16: =MAX(0,MIN(F16-G16,Budget!$B$32-J15)) -> 0 | J16: =J15+I16 -> 4000 | K16: =MAX(0,F16-G16-I16) -> 643.55 | L16: =K16*Budget!$B$36 -> 386.13 | M16: =MAX(0,L16-Calcul!AY14) -> 0 | N16: =K16-L16+M16 -> 257.42 | O16: =O15+N16 -> 264.52 | P16: =Calcul!AZ14 -> 9615.07 | Q16: =IF(F16<0,"Budget négatif !","") | R16: =IF(H16>=Budget!$B$29,1,0) -> 0 | S16: =IF(J16>=Budget!$B$32,1,0) -> 1 | T16: =IF(P16<=0.01,1,0) -> 0 | V16: Survolez un titre de colonne pour son explication. | AA16: =Budget!$B$29 -> 4000 | AB16: =Budget!$B$32 -> 4000
A17: 13 | B17: =EDATE(Budget!$B$28,A17-1) -> 46753 | C17: =Budget!$B$7 -> 2900 | D17: =Budget!$B$18+Budget!$B$25 -> 1725 | E17: =Calcul!AX15 -> 531.45 | F17: =C17-D17-E17 -> 643.55 | G17: =IF(B17<=Budget!$B$30,MAX(0,MIN(F17,Budget!$B$29-H16)),0) -> 0 | H17: =H16+G17 -> 3511.3 | I17: =MAX(0,MIN(F17-G17,Budget!$B$32-J16)) -> 0 | J17: =J16+I17 -> 4000 | K17: =MAX(0,F17-G17-I17) -> 643.55 | L17: =K17*Budget!$B$36 -> 386.13 | M17: =MAX(0,L17-Calcul!AY15) -> 0 | N17: =K17-L17+M17 -> 257.42 | O17: =O16+N17 -> 521.94 | P17: =Calcul!AZ15 -> 8746.31 | Q17: =IF(F17<0,"Budget négatif !","") | R17: =IF(H17>=Budget!$B$29,1,0) -> 0 | S17: =IF(J17>=Budget!$B$32,1,0) -> 1 | T17: =IF(P17<=0.01,1,0) -> 0 | AA17: =Budget!$B$29 -> 4000 | AB17: =Budget!$B$32 -> 4000
A18: 14 | B18: =EDATE(Budget!$B$28,A18-1) -> 46784 | C18: =Budget!$B$7 -> 2900 | D18: =Budget!$B$18+Budget!$B$25 -> 1725 | E18: =Calcul!AX16 -> 531.45 | F18: =C18-D18-E18 -> 643.55 | G18: =IF(B18<=Budget!$B$30,MAX(0,MIN(F18,Budget!$B$29-H17)),0) -> 0 | H18: =H17+G18 -> 3511.3 | I18: =MAX(0,MIN(F18-G18,Budget!$B$32-J17)) -> 0 | J18: =J17+I18 -> 4000 | K18: =MAX(0,F18-G18-I18) -> 643.55 | L18: =K18*Budget!$B$36 -> 386.13 | M18: =MAX(0,L18-Calcul!AY16) -> 0 | N18: =K18-L18+M18 -> 257.42 | O18: =O17+N18 -> 779.36 | P18: =Calcul!AZ16 -> 7869 | Q18: =IF(F18<0,"Budget négatif !","") | R18: =IF(H18>=Budget!$B$29,1,0) -> 0 | S18: =IF(J18>=Budget!$B$32,1,0) -> 1 | T18: =IF(P18<=0.01,1,0) -> 0 | AA18: =Budget!$B$29 -> 4000 | AB18: =Budget!$B$32 -> 4000
A19: 15 | B19: =EDATE(Budget!$B$28,A19-1) -> 46813 | C19: =Budget!$B$7 -> 2900 | D19: =Budget!$B$18+Budget!$B$25 -> 1725 | E19: =Calcul!AX17 -> 459.05 | F19: =C19-D19-E19 -> 715.95 | G19: =IF(B19<=Budget!$B$30,MAX(0,MIN(F19,Budget!$B$29-H18)),0) -> 0 | H19: =H18+G19 -> 3511.3 | I19: =MAX(0,MIN(F19-G19,Budget!$B$32-J18)) -> 0 | J19: =J18+I19 -> 4000 | K19: =MAX(0,F19-G19-I19) -> 715.95 | L19: =K19*Budget!$B$36 -> 429.57 | M19: =MAX(0,L19-Calcul!AY17) -> 0 | N19: =K19-L19+M19 -> 286.38 | O19: =O18+N19 -> 1065.74 | P19: =Calcul!AZ17 -> 7012.08 | Q19: =IF(F19<0,"Budget négatif !","") | R19: =IF(H19>=Budget!$B$29,1,0) -> 0 | S19: =IF(J19>=Budget!$B$32,1,0) -> 1 | T19: =IF(P19<=0.01,1,0) -> 0 | AA19: =Budget!$B$29 -> 4000 | AB19: =Budget!$B$32 -> 4000
A20: 16 | B20: =EDATE(Budget!$B$28,A20-1) -> 46844 | C20: =Budget!$B$7 -> 2900 | D20: =Budget!$B$18+Budget!$B$25 -> 1725 | E20: =Calcul!AX18 -> 459.05 | F20: =C20-D20-E20 -> 715.95 | G20: =IF(B20<=Budget!$B$30,MAX(0,MIN(F20,Budget!$B$29-H19)),0) -> 0 | H20: =H19+G20 -> 3511.3 | I20: =MAX(0,MIN(F20-G20,Budget!$B$32-J19)) -> 0 | J20: =J19+I20 -> 4000 | K20: =MAX(0,F20-G20-I20) -> 715.95 | L20: =K20*Budget!$B$36 -> 429.57 | M20: =MAX(0,L20-Calcul!AY18) -> 0 | N20: =K20-L20+M20 -> 286.38 | O20: =O19+N20 -> 1352.12 | P20: =Calcul!AZ18 -> 6151.39 | Q20: =IF(F20<0,"Budget négatif !","") | R20: =IF(H20>=Budget!$B$29,1,0) -> 0 | S20: =IF(J20>=Budget!$B$32,1,0) -> 1 | T20: =IF(P20<=0.01,1,0) -> 0 | AA20: =Budget!$B$29 -> 4000 | AB20: =Budget!$B$32 -> 4000
A21: 17 | B21: =EDATE(Budget!$B$28,A21-1) -> 46874 | C21: =Budget!$B$7 -> 2900 | D21: =Budget!$B$18+Budget!$B$25 -> 1725 | E21: =Calcul!AX19 -> 459.05 | F21: =C21-D21-E21 -> 715.95 | G21: =IF(B21<=Budget!$B$30,MAX(0,MIN(F21,Budget!$B$29-H20)),0) -> 0 | H21: =H20+G21 -> 3511.3 | I21: =MAX(0,MIN(F21-G21,Budget!$B$32-J20)) -> 0 | J21: =J20+I21 -> 4000 | K21: =MAX(0,F21-G21-I21) -> 715.95 | L21: =K21*Budget!$B$36 -> 429.57 | M21: =MAX(0,L21-Calcul!AY19) -> 0 | N21: =K21-L21+M21 -> 286.38 | O21: =O20+N21 -> 1638.5 | P21: =Calcul!AZ19 -> 5286.9 | Q21: =IF(F21<0,"Budget négatif !","") | R21: =IF(H21>=Budget!$B$29,1,0) -> 0 | S21: =IF(J21>=Budget!$B$32,1,0) -> 1 | T21: =IF(P21<=0.01,1,0) -> 0 | AA21: =Budget!$B$29 -> 4000 | AB21: =Budget!$B$32 -> 4000
A22: 18 | B22: =EDATE(Budget!$B$28,A22-1) -> 46905 | C22: =Budget!$B$7 -> 2900 | D22: =Budget!$B$18+Budget!$B$25 -> 1725 | E22: =Calcul!AX20 -> 459.05 | F22: =C22-D22-E22 -> 715.95 | G22: =IF(B22<=Budget!$B$30,MAX(0,MIN(F22,Budget!$B$29-H21)),0) -> 0 | H22: =H21+G22 -> 3511.3 | I22: =MAX(0,MIN(F22-G22,Budget!$B$32-J21)) -> 0 | J22: =J21+I22 -> 4000 | K22: =MAX(0,F22-G22-I22) -> 715.95 | L22: =K22*Budget!$B$36 -> 429.57 | M22: =MAX(0,L22-Calcul!AY20) -> 0 | N22: =K22-L22+M22 -> 286.38 | O22: =O21+N22 -> 1924.88 | P22: =Calcul!AZ20 -> 4418.62 | Q22: =IF(F22<0,"Budget négatif !","") | R22: =IF(H22>=Budget!$B$29,1,0) -> 0 | S22: =IF(J22>=Budget!$B$32,1,0) -> 1 | T22: =IF(P22<=0.01,1,0) -> 0 | AA22: =Budget!$B$29 -> 4000 | AB22: =Budget!$B$32 -> 4000
A23: 19 | B23: =EDATE(Budget!$B$28,A23-1) -> 46935 | C23: =Budget!$B$7 -> 2900 | D23: =Budget!$B$18+Budget!$B$25 -> 1725 | E23: =Calcul!AX21 -> 340.3 | F23: =C23-D23-E23 -> 834.7 | G23: =IF(B23<=Budget!$B$30,MAX(0,MIN(F23,Budget!$B$29-H22)),0) -> 0 | H23: =H22+G23 -> 3511.3 | I23: =MAX(0,MIN(F23-G23,Budget!$B$32-J22)) -> 0 | J23: =J22+I23 -> 4000 | K23: =MAX(0,F23-G23-I23) -> 834.7 | L23: =K23*Budget!$B$36 -> 500.82 | M23: =MAX(0,L23-Calcul!AY21) -> 0 | N23: =K23-L23+M23 -> 333.88 | O23: =O22+N23 -> 2258.76 | P23: =Calcul!AZ21 -> 3594.26 | Q23: =IF(F23<0,"Budget négatif !","") | R23: =IF(H23>=Budget!$B$29,1,0) -> 0 | S23: =IF(J23>=Budget!$B$32,1,0) -> 1 | T23: =IF(P23<=0.01,1,0) -> 0 | AA23: =Budget!$B$29 -> 4000 | AB23: =Budget!$B$32 -> 4000
A24: 20 | B24: =EDATE(Budget!$B$28,A24-1) -> 46966 | C24: =Budget!$B$7 -> 2900 | D24: =Budget!$B$18+Budget!$B$25 -> 1725 | E24: =Calcul!AX22 -> 340.3 | F24: =C24-D24-E24 -> 834.7 | G24: =IF(B24<=Budget!$B$30,MAX(0,MIN(F24,Budget!$B$29-H23)),0) -> 0 | H24: =H23+G24 -> 3511.3 | I24: =MAX(0,MIN(F24-G24,Budget!$B$32-J23)) -> 0 | J24: =J23+I24 -> 4000 | K24: =MAX(0,F24-G24-I24) -> 834.7 | L24: =K24*Budget!$B$36 -> 500.82 | M24: =MAX(0,L24-Calcul!AY22) -> 0 | N24: =K24-L24+M24 -> 333.88 | O24: =O23+N24 -> 2592.64 | P24: =Calcul!AZ22 -> 2766.83 | Q24: =IF(F24<0,"Budget négatif !","") | R24: =IF(H24>=Budget!$B$29,1,0) -> 0 | S24: =IF(J24>=Budget!$B$32,1,0) -> 1 | T24: =IF(P24<=0.01,1,0) -> 0 | AA24: =Budget!$B$29 -> 4000 | AB24: =Budget!$B$32 -> 4000
A25: 21 | B25: =EDATE(Budget!$B$28,A25-1) -> 46997 | C25: =Budget!$B$7 -> 2900 | D25: =Budget!$B$18+Budget!$B$25 -> 1725 | E25: =Calcul!AX23 -> 340.3 | F25: =C25-D25-E25 -> 834.7 | G25: =IF(B25<=Budget!$B$30,MAX(0,MIN(F25,Budget!$B$29-H24)),0) -> 0 | H25: =H24+G25 -> 3511.3 | I25: =MAX(0,MIN(F25-G25,Budget!$B$32-J24)) -> 0 | J25: =J24+I25 -> 4000 | K25: =MAX(0,F25-G25-I25) -> 834.7 | L25: =K25*Budget!$B$36 -> 500.82 | M25: =MAX(0,L25-Calcul!AY23) -> 0 | N25: =K25-L25+M25 -> 333.88 | O25: =O24+N25 -> 2926.52 | P25: =Calcul!AZ23 -> 1936.31 | Q25: =IF(F25<0,"Budget négatif !","") | R25: =IF(H25>=Budget!$B$29,1,0) -> 0 | S25: =IF(J25>=Budget!$B$32,1,0) -> 1 | T25: =IF(P25<=0.01,1,0) -> 0 | AA25: =Budget!$B$29 -> 4000 | AB25: =Budget!$B$32 -> 4000
A26: 22 | B26: =EDATE(Budget!$B$28,A26-1) -> 47027 | C26: =Budget!$B$7 -> 2900 | D26: =Budget!$B$18+Budget!$B$25 -> 1725 | E26: =Calcul!AX24 -> 340.3 | F26: =C26-D26-E26 -> 834.7 | G26: =IF(B26<=Budget!$B$30,MAX(0,MIN(F26,Budget!$B$29-H25)),0) -> 0 | H26: =H25+G26 -> 3511.3 | I26: =MAX(0,MIN(F26-G26,Budget!$B$32-J25)) -> 0 | J26: =J25+I26 -> 4000 | K26: =MAX(0,F26-G26-I26) -> 834.7 | L26: =K26*Budget!$B$36 -> 500.82 | M26: =MAX(0,L26-Calcul!AY24) -> 0 | N26: =K26-L26+M26 -> 333.88 | O26: =O25+N26 -> 3260.4 | P26: =Calcul!AZ24 -> 1102.7 | Q26: =IF(F26<0,"Budget négatif !","") | R26: =IF(H26>=Budget!$B$29,1,0) -> 0 | S26: =IF(J26>=Budget!$B$32,1,0) -> 1 | T26: =IF(P26<=0.01,1,0) -> 0 | AA26: =Budget!$B$29 -> 4000 | AB26: =Budget!$B$32 -> 4000
A27: 23 | B27: =EDATE(Budget!$B$28,A27-1) -> 47058 | C27: =Budget!$B$7 -> 2900 | D27: =Budget!$B$18+Budget!$B$25 -> 1725 | E27: =Calcul!AX25 -> 279.92459 | F27: =C27-D27-E27 -> 895.07541 | G27: =IF(B27<=Budget!$B$30,MAX(0,MIN(F27,Budget!$B$29-H26)),0) -> 0 | H27: =H26+G27 -> 3511.3 | I27: =MAX(0,MIN(F27-G27,Budget!$B$32-J26)) -> 0 | J27: =J26+I27 -> 4000 | K27: =MAX(0,F27-G27-I27) -> 895.07541 | L27: =K27*Budget!$B$36 -> 537.04525 | M27: =MAX(0,L27-Calcul!AY25) -> 0 | N27: =K27-L27+M27 -> 358.03016 | O27: =O26+N27 -> 3618.4302 | P27: =Calcul!AZ25 -> 290.12 | Q27: =IF(F27<0,"Budget négatif !","") | R27: =IF(H27>=Budget!$B$29,1,0) -> 0 | S27: =IF(J27>=Budget!$B$32,1,0) -> 1 | T27: =IF(P27<=0.01,1,0) -> 0 | AA27: =Budget!$B$29 -> 4000 | AB27: =Budget!$B$32 -> 4000
A28: 24 | B28: =EDATE(Budget!$B$28,A28-1) -> 47088 | C28: =Budget!$B$7 -> 2900 | D28: =Budget!$B$18+Budget!$B$25 -> 1725 | E28: =Calcul!AX26 -> 245.3 | F28: =C28-D28-E28 -> 929.7 | G28: =IF(B28<=Budget!$B$30,MAX(0,MIN(F28,Budget!$B$29-H27)),0) -> 0 | H28: =H27+G28 -> 3511.3 | I28: =MAX(0,MIN(F28-G28,Budget!$B$32-J27)) -> 0 | J28: =J27+I28 -> 4000 | K28: =MAX(0,F28-G28-I28) -> 929.7 | L28: =K28*Budget!$B$36 -> 557.82 | M28: =MAX(0,L28-Calcul!AY26) -> 511.82 | N28: =K28-L28+M28 -> 883.7 | O28: =O27+N28 -> 4502.1302 | P28: =Calcul!AZ26 -> 0 | Q28: =IF(F28<0,"Budget négatif !","") | R28: =IF(H28>=Budget!$B$29,1,0) -> 0 | S28: =IF(J28>=Budget!$B$32,1,0) -> 1 | T28: =IF(P28<=0.01,1,0) -> 1 | AA28: =Budget!$B$29 -> 4000 | AB28: =Budget!$B$32 -> 4000
... A304: 300 | B304: =EDATE(Budget!$B$28,A304-1) -> 55488 | C304: =Budget!$B$7 -> 2900 | D304: =Budget!$B$18+Budget!$B$25 -> 1725 | E304: =Calcul!AX302 -> 0 | F304: =C304-D304-E304 -> 1175 | G304: =IF(B304<=Budget!$B$30,MAX(0,MIN(F304,Budget!$B$29-H303)),0) -> 0 | H304: =H303+G304 -> 3511.3 | I304: =MAX(0,MIN(F304-G304,Budget!$B$32-J303)) -> 0 | J304: =J303+I304 -> 4000 | K304: =MAX(0,F304-G304-I304) -> 1175 | L304: =K304*Budget!$B$36 -> 705 | M304: =MAX(0,L304-Calcul!AY302) -> 705 | N304: =K304-L304+M304 -> 1175 | O304: =O303+N304 -> 328802.13 | P304: =Calcul!AZ302 -> 0 | Q304: =IF(F304<0,"Budget négatif !","") | R304: =IF(H304>=Budget!$B$29,1,0) -> 0 | S304: =IF(J304>=Budget!$B$32,1,0) -> 1 | T304: =IF(P304<=0.01,1,0) -> 1 | AA304: =Budget!$B$29 -> 4000 | AB304: =Budget!$B$32 -> 4000

Sheet Calcul
A1: ⚠ Onglet technique : ne rien modifier | B1: =IF(Crédits!A5="","Crédit 1",Crédits!A5) -> Prêt auto | J1: =IF(Crédits!A6="","Crédit 2",Crédits!A6) -> Carte revolving | R1: =IF(Crédits!A7="","Crédit 3",Crédits!A7) -> Prêt travaux | Z1: =IF(Crédits!A8="","Crédit 4",Crédits!A8) -> Prêt étudiant | AH1: =IF(Crédits!A9="","Crédit 5",Crédits!A9) -> Dette perso A | AP1: =IF(Crédits!A10="","Crédit 6",Crédits!A10) -> Dette perso B | AX1: TOTAUX (repris dans l'onglet Plan)
A2: Mois (survolez pour la légende) | B2: Solde début | C2: Intérêts | D2: Mensualité payée | E2: Solde après mens. | F2: Remb. anticipé | G2: Solde fin | H2: Solde fin sans anticip. | I2: Intérêts sans anticip. | J2: Solde début | K2: Intérêts | L2: Mensualité payée | M2: Solde après mens. | N2: Remb. anticipé | O2: Solde fin | P2: Solde fin sans anticip. | Q2: Intérêts sans anticip. | R2: Solde début | S2: Intérêts | T2: Mensualité payée | U2: Solde après mens. | V2: Remb. anticipé | W2: Solde fin | X2: Solde fin sans anticip. | Y2: Intérêts sans anticip. | Z2: Solde début | AA2: Intérêts | AB2: Mensualité payée | AC2: Solde après mens. | AD2: Remb. anticipé | AE2: Solde fin | AF2: Solde fin sans anticip. | AG2: Intérêts sans anticip. | AH2: Solde début | AI2: Intérêts | AJ2: Mensualité payée | AK2: Solde après mens. | AL2: Remb. anticipé | AM2: Solde fin | AN2: Solde fin sans anticip. | AO2: Intérêts sans anticip. | AP2: Solde début | AQ2: Intérêts | AR2: Mensualité payée | AS2: Solde après mens. | AT2: Remb. anticipé | AU2: Solde fin | AV2: Solde fin sans anticip. | AW2: Intérêts sans anticip. | AX2: Total mensualités | AY2: Total remb. anticipé | AZ2: Total dettes fin | BA2: Total intérêts | BB2: Total intérêts sans anticip.
A3: 1 | B3: =MAX(0,N(Crédits!$C$5)) -> 8200 | C3: =B3*N(Crédits!$D$5)/12 -> 33.483333 | D3: =MIN(N(Crédits!$E$5),B3+C3) -> 245.3 | E3: =ROUND(B3+C3-D3,2) -> 7988.18 | F3: =IF(Crédits!$K$5="",0,MAX(0,MIN(E3,Plan!$L$5-(IF(Crédits!$K$6="",0,IF(Crédits!$K$6<Crédits!$K$5,M3,0))+IF(Crédits!$K$7="",0,IF(Crédits!$K$7<Crédits!$K$5,U3,0))+IF(Crédits!$K$8="",0,IF(Crédits!$K$8<Crédits!$K$5,AC3,0))+IF(Crédits!$K$9="",0,IF(Crédits!$K$9<Crédits!$K$5,AK3,0))+IF(Crédits!$K$10="",0,IF(Crédits!$K$10<Crédits!$K$5,AS3,0)))))) -> 0 | G3: =ROUND(E3-F3,2) -> 7988.18 | H3: =ROUND(MAX(0,N(Crédits!$C$5))+I3-MIN(N(Crédits!$E$5),MAX(0,N(Crédits!$C$5))+I3),2) -> 7988.18 | I3: =MAX(0,N(Crédits!$C$5))*N(Crédits!$D$5)/12 -> 33.483333 | J3: =MAX(0,N(Crédits!$C$6)) -> 1850 | K3: =J3*N(Crédits!$D$6)/12 -> 29.1375 | L3: =MIN(N(Crédits!$E$6),J3+K3) -> 72.4 | M3: =ROUND(J3+K3-L3,2) -> 1806.74 | N3: =IF(Crédits!$K$6="",0,MAX(0,MIN(M3,Plan!$L$5-(IF(Crédits!$K$5="",0,IF(Crédits!$K$5<Crédits!$K$6,E3,0))+IF(Crédits!$K$7="",0,IF(Crédits!$K$7<Crédits!$K$6,U3,0))+IF(Crédits!$K$8="",0,IF(Crédits!$K$8<Crédits!$K$6,AC3,0))+IF(Crédits!$K$9="",0,IF(Crédits!$K$9<Crédits!$K$6,AK3,0))+IF(Crédits!$K$10="",0,IF(Crédits!$K$10<Crédits!$K$6,AS3,0)))))) -> 0 | O3: =ROUND(M3-N3,2) -> 1806.74 | P3: =ROUND(MAX(0,N(Crédits!$C$6))+Q3-MIN(N(Crédits!$E$6),MAX(0,N(Crédits!$C$6))+Q3),2) -> 1806.74 | Q3: =MAX(0,N(Crédits!$C$6))*N(Crédits!$D$6)/12 -> 29.1375 | R3: =MAX(0,N(Crédits!$C$7)) -> 3400 | S3: =R3*N(Crédits!$D$7)/12 -> 17.425 | T3: =MIN(N(Crédits!$E$7),R3+S3) -> 118.75 | U3: =ROUND(R3+S3-T3,2) -> 3298.68 | V3: =IF(Crédits!$K$7="",0,MAX(0,MIN(U3,Plan!$L$5-(IF(Crédits!$K$5="",0,IF(Crédits!$K$5<Crédits!$K$7,E3,0))+IF(Crédits!$K$6="",0,IF(Crédits!$K$6<Crédits!$K$7,M3,0))+IF(Crédits!$K$8="",0,IF(Crédits!$K$8<Crédits!$K$7,AC3,0))+IF(Crédits!$K$9="",0,IF(Crédits!$K$9<Crédits!$K$7,AK3,0))+IF(Crédits!$K$10="",0,IF(Crédits!$K$10<Crédits!$K$7,AS3,0)))))) -> 0 | W3: =ROUND(U3-V3,2) -> 3298.68 | X3: =ROUND(MAX(0,N(Crédits!$C$7))+Y3-MIN(N(Crédits!$E$7),MAX(0,N(Crédits!$C$7))+Y3),2) -> 3298.68 | Y3: =MAX(0,N(Crédits!$C$7))*N(Crédits!$D$7)/12 -> 17.425 | Z3: =MAX(0,N(Crédits!$C$8)) -> 2100 | AA3: =Z3*N(Crédits!$D$8)/12 -> 2.1 | AB3: =MIN(N(Crédits!$E$8),Z3+AA3) -> 95 | AC3: =ROUND(Z3+AA3-AB3,2) -> 2007.1 | AD3: =IF(Crédits!$K$8="",0,MAX(0,MIN(AC3,Plan!$L$5-(IF(Crédits!$K$5="",0,IF(Crédits!$K$5<Crédits!$K$8,E3,0))+IF(Crédits!$K$6="",0,IF(Crédits!$K$6<Crédits!$K$8,M3,0))+IF(Crédits!$K$7="",0,IF(Crédits!$K$7<Crédits!$K$8,U3,0))+IF(Crédits!$K$9="",0,IF(Crédits!$K$9<Crédits!$K$8,AK3,0))+IF(Crédits!$K$10="",0,IF(Crédits!$K$10<Crédits!$K$8,AS3,0)))))) -> 0 | AE3: =ROUND(AC3-AD3,2) -> 2007.1 | AF3: =ROUND(MAX(0,N(Crédits!$C$8))+AG3-MIN(N(Crédits!$E$8),MAX(0,N(Crédits!$C$8))+AG3),2) -> 2007.1 | AG3: =MAX(0,N(Crédits!$C$8))*N(Crédits!$D$8)/12 -> 2.1 | AH3: =MAX(0,N(Crédits!$C$9)) -> 600 | AI3: =AH3*N(Crédits!$D$9)/12 -> 0 | AJ3: =MIN(N(Crédits!$E$9),AH3+AI3) -> 150 | AK3: =ROUND(AH3+AI3-AJ3,2) -> 450 | AL3: =IF(Crédits!$K$9="",0,MAX(0,MIN(AK3,Plan!$L$5-(IF(Crédits!$K$5="",0,IF(Crédits!$K$5<Crédits!$K$9,E3,0))+IF(Crédits!$K$6="",0,IF(Crédits!$K$6<Crédits!$K$9,M3,0))+IF(Crédits!$K$7="",0,IF(Crédits!$K$7<Crédits!$K$9,U3,0))+IF(Crédits!$K$8="",0,IF(Crédits!$K$8<Crédits!$K$9,AC3,0))+IF(Crédits!$K$10="",0,IF(Crédits!$K$10<Crédits!$K$9,AS3,0)))))) -> 0 | AM3: =ROUND(AK3-AL3,2) -> 450 | AN3: =ROUND(MAX(0,N(Crédits!$C$9))+AO3-MIN(N(Crédits!$E$9),MAX(0,N(Crédits!$C$9))+AO3),2) -> 450 | AO3: =MAX(0,N(Crédits!$C$9))*N(Crédits!$D$9)/12 -> 0 | AP3: =MAX(0,N(Crédits!$C$10)) -> 250 | AQ3: =AP3*N(Crédits!$D$10)/12 -> 0 | AR3: =MIN(N(Crédits!$E$10),AP3+AQ3) -> 50 | AS3: =ROUND(AP3+AQ3-AR3,2) -> 200 | AT3: =IF(Crédits!$K$10="",0,MAX(0,MIN(AS3,Plan!$L$5-(IF(Crédits!$K$5="",0,IF(Crédits!$K$5<Crédits!$K$10,E3,0))+IF(Crédits!$K$6="",0,IF(Crédits!$K$6<Crédits!$K$10,M3,0))+IF(Crédits!$K$7="",0,IF(Crédits!$K$7<Crédits!$K$10,U3,0))+IF(Crédits!$K$8="",0,IF(Crédits!$K$8<Crédits!$K$10,AC3,0))+IF(Crédits!$K$9="",0,IF(Crédits!$K$9<Crédits!$K$10,AK3,0)))))) -> 0 | AU3: =ROUND(AS3-AT3,2) -> 200 | AV3: =ROUND(MAX(0,N(Crédits!$C$10))+AW3-MIN(N(Crédits!$E$10),MAX(0,N(Crédits!$C$10))+AW3),2) -> 200 | AW3: =MAX(0,N(Crédits!$C$10))*N(Crédits!$D$10)/12 -> 0 | AX3: =D3+L3+T3+AB3+AJ3+AR3 -> 731.45 | AY3: =F3+N3+V3+AD3+AL3+AT3 -> 0 | AZ3: =G3+O3+W3+AE3+AM3+AU3 -> 15750.7 | BA3: =C3+K3+S3+AA3+AI3+AQ3 -> 82.145833 | BB3: =I3+Q3+Y3+AG3+AO3+AW3 -> 82.145833
A4: 2 | B4: =G3 -> 7988.18 | C4: =B4*N(Crédits!$D$5)/12 -> 32.618402 | D4: =MIN(N(Crédits!$E$5),B4+C4) -> 245.3 | E4: =ROUND(B4+C4-D4,2) -> 7775.5 | F4: =IF(Crédits!$K$5="",0,MAX(0,MIN(E4,Plan!$L$6-(IF(Crédits!$K$6="",0,IF(Crédits!$K$6<Crédits!$K$5,M4,0))+IF(Crédits!$K$7="",0,IF(Crédits!$K$7<Crédits!$K$5,U4,0))+IF(Crédits!$K$8="",0,IF(Crédits!$K$8<Crédits!$K$5,AC4,0))+IF(Crédits!$K$9="",0,IF(Crédits!$K$9<Crédits!$K$5,AK4,0))+IF(Crédits!$K$10="",0,IF(Crédits!$K$10<Crédits!$K$5,AS4,0)))))) -> 0 | G4: =ROUND(E4-F4,2) -> 7775.5 | H4: =ROUND(H3+I4-MIN(N(Crédits!$E$5),H3+I4),2) -> 7775.5 | I4: =H3*N(Crédits!$D$5)/12 -> 32.618402 | J4: =O3 -> 1806.74 | K4: =J4*N(Crédits!$D$6)/12 -> 28.456155 | L4: =MIN(N(Crédits!$E$6),J4+K4) -> 72.4 | M4: =ROUND(J4+K4-L4,2) -> 1762.8 | N4: =IF(Crédits!$K$6="",0,MAX(0,MIN(M4,Plan!$L$6-(IF(Crédits!$K$5="",0,IF(Crédits!$K$5<Crédits!$K$6,E4,0))+IF(Crédits!$K$7="",0,IF(Crédits!$K$7<Crédits!$K$6,U4,0))+IF(Crédits!$K$8="",0,IF(Crédits!$K$8<Crédits!$K$6,AC4,0))+IF(Crédits!$K$9="",0,IF(Crédits!$K$9<Crédits!$K$6,AK4,0))+IF(Crédits!$K$10="",0,IF(Crédits!$K$10<Crédits!$K$6,AS4,0)))))) -> 0 | O4: =ROUND(M4-N4,2) -> 1762.8 | P4: =ROUND(P3+Q4-MIN(N(Crédits!$E$6),P3+Q4),2) -> 1762.8 | Q4: =P3*N(Crédits!$D$6)/12 -> 28.456155 | R4: =W3 -> 3298.68 | S4: =R4*N(Crédits!$D$7)/12 -> 16.905735 | T4: =MIN(N(Crédits!$E$7),R4+S4) -> 118.75 | U4: =ROUND(R4+S4-T4,2) -> 3196.84 | V4: =IF(Crédits!$K$7="",0,MAX(0,MIN(U4,Plan!$L$6-(IF(Crédits!$K$5="",0,IF(Crédits!$K$5<Crédits!$K$7,E4,0))+IF(Crédits!$K$6="",0,IF(Crédits!$K$6<Crédits!$K$7,M4,0))+IF(Crédits!$K$8="",0,IF(Crédits!$K$8<Crédits!$K$7,AC4,0))+IF(Crédits!$K$9="",0,IF(Crédits!$K$9<Crédits!$K$7,AK4,0))+IF(Crédits!$K$10="",0,IF(Crédits!$K$10<Crédits!$K$7,AS4,0)))))) -> 0 | W4: =ROUND(U4-V4,2) -> 3196.84 | X4: =ROUND(X3+Y4-MIN(N(Crédits!$E$7),X3+Y4),2) -> 3196.84 | Y4: =X3*N(Crédits!$D$7)/12 -> 16.905735 | Z4: =AE3 -> 2007.1 | AA4: =Z4*N(Crédits!$D$8)/12 -> 2.0071 | AB4: =MIN(N(Crédits!$E$8),Z4+AA4) -> 95 | AC4: =ROUND(Z4+AA4-AB4,2) -> 1914.11 | AD4: =IF(Crédits!$K$8="",0,MAX(0,MIN(AC4,Plan!$L$6-(IF(Crédits!$K$5="",0,IF(Crédits!$K$5<Crédits!$K$8,E4,0))+IF(Crédits!$K$6="",0,IF(Crédits!$K$6<Crédits!$K$8,M4,0))+IF(Crédits!$K$7="",0,IF(Crédits!$K$7<Crédits!$K$8,U4,0))+IF(Crédits!$K$9="",0,IF(Crédits!$K$9<Crédits!$K$8,AK4,0))+IF(Crédits!$K$10="",0,IF(Crédits!$K$10<Crédits!$K$8,AS4,0)))))) -> 0 | AE4: =ROUND(AC4-AD4,2) -> 1914.11 | AF4: =ROUND(AF3+AG4-MIN(N(Crédits!$E$8),AF3+AG4),2) -> 1914.11 | AG4: =AF3*N(Crédits!$D$8)/12 -> 2.0071 | AH4: =AM3 -> 450 | AI4: =AH4*N(Crédits!$D$9)/12 -> 0 | AJ4: =MIN(N(Crédits!$E$9),AH4+AI4) -> 150 | AK4: =ROUND(AH4+AI4-AJ4,2) -> 300 | AL4: =IF(Crédits!$K$9="",0,MAX(0,MIN(AK4,Plan!$L$6-(IF(Crédits!$K$5="",0,IF(Crédits!$K$5<Crédits!$K$9,E4,0))+IF(Crédits!$K$6="",0,IF(Crédits!$K$6<Crédits!$K$9,M4,0))+IF(Crédits!$K$7="",0,IF(Crédits!$K$7<Crédits!$K$9,U4,0))+IF(Crédits!$K$8="",0,IF(Crédits!$K$8<Crédits!$K$9,AC4,0))+IF(Crédits!$K$10="",0,IF(Crédits!$K$10<Crédits!$K$9,AS4,0)))))) -> 0 | AM4: =ROUND(AK4-AL4,2) -> 300 | AN4: =ROUND(AN3+AO4-MIN(N(Crédits!$E$9),AN3+AO4),2) -> 300 | AO4: =AN3*N(Crédits!$D$9)/12 -> 0 | AP4: =AU3 -> 200 | AQ4: =AP4*N(Crédits!$D$10)/12 -> 0 | AR4: =MIN(N(Crédits!$E$10),AP4+AQ4) -> 50 | AS4: =ROUND(AP4+AQ4-AR4,2) -> 150 | AT4: =IF(Crédits!$K$10="",0,MAX(0,MIN(AS4,Plan!$L$6-(IF(Crédits!$K$5="",0,IF(Crédits!$K$5<Crédits!$K$10,E4,0))+IF(Crédits!$K$6="",0,IF(Crédits!$K$6<Crédits!$K$10,M4,0))+IF(Crédits!$K$7="",0,IF(Crédits!$K$7<Crédits!$K$10,U4,0))+IF(Crédits!$K$8="",0,IF(Crédits!$K$8<Crédits!$K$10,AC4,0))+IF(Crédits!$K$9="",0,IF(Crédits!$K$9<Crédits!$K$10,AK4,0)))))) -> 0 | AU4: =ROUND(AS4-AT4,2) -> 150 | AV4: =ROUND(AV3+AW4-MIN(N(Crédits!$E$10),AV3+AW4),2) -> 150 | AW4: =AV3*N(Crédits!$D$10)/12 -> 0 | AX4: =D4+L4+T4+AB4+AJ4+AR4 -> 731.45 | AY4: =F4+N4+V4+AD4+AL4+AT4 -> 0 | AZ4: =G4+O4+W4+AE4+AM4+AU4 -> 15099.25 | BA4: =C4+K4+S4+AA4+AI4+AQ4 -> 79.987392 | BB4: =I4+Q4+Y4+AG4+AO4+AW4 -> 79.987392
A5: 3 | B5: =G4 -> 7775.5 | C5: =B5*N(Crédits!$D$5)/12 -> 31.749958 | D5: =MIN(N(Crédits!$E$5),B5+C5) -> 245.3 | E5: =ROUND(B5+C5-D5,2) -> 7561.95 | F5: =IF(Crédits!$K$5="",0,MAX(0,MIN(E5,Plan!$L$7-(IF(Crédits!$K$6="",0,IF(Crédits!$K$6<Crédits!$K$5,M5,0))+IF(Crédits!$K$7="",0,IF(Crédits!$K$7<Crédits!$K$5,U5,0))+IF(Crédits!$K$8="",0,IF(Crédits!$K$8<Crédits!$K$5,AC5,0))+IF(Crédits!$K$9="",0,IF(Crédits!$K$9<Crédits!$K$5,AK5,0))+IF(Crédits!$K$10="",0,IF(Crédits!$K$10<Crédits!$K$5,AS5,0)))))) -> 0 | G5: =ROUND(E5-F5,2) -> 7561.95 | H5: =ROUND(H4+I5-MIN(N(Crédits!$E$5),H4+I5),2) -> 7561.95 | I5: =H4*N(Crédits!$D$5)/12 -> 31.749958 | J5: =O4 -> 1762.8 | K5: =J5*N(Crédits!$D$6)/12 -> 27.7641 | L5: =MIN(N(Crédits!$E$6),J5+K5) -> 72.4 | M5: =ROUND(J5+K5-L5,2) -> 1718.16 | N5: =IF(Crédits!$K$6="",0,MAX(0,MIN(M5,Plan!$L$7-(IF(Crédits!$K$5="",0,IF(Crédits!$K$5<Crédits!$K$6,E5,0))+IF(Crédits!$K$7="",0,IF(Crédits!$K$7<Crédits!$K$6,U5,0))+IF(Crédits!$K$8="",0,IF(Crédits!$K$8<Crédits!$K$6,AC5,0))+IF(Crédits!$K$9="",0,IF(Crédits!$K$9<Crédits!$K$6,AK5,0))+IF(Crédits!$K$10="",0,IF(Crédits!$K$10<Crédits!$K$6,AS5,0)))))) -> 0 | O5: =ROUND(M5-N5,2) -> 1718.16 | P5: =ROUND(P4+Q5-MIN(N(Crédits!$E$6),P4+Q5),2) -> 1718.16 | Q5: =P4*N(Crédits!$D$6)/12 -> 27.7641 | R5: =W4 -> 3196.84 | S5: =R5*N(Crédits!$D$7)/12 -> 16.383805 | T5: =MIN(N(Crédits!$E$7),R5+S5) -> 118.75 | U5: =ROUND(R5+S5-T5,2) -> 3094.47 | V5: =IF(Crédits!$K$7="",0,MAX(0,MIN(U5,Plan!$L$7-(IF(Crédits!$K$5="",0,IF(Crédits!$K$5<Crédits!$K$7,E5,0))+IF(Crédits!$K$6="",0,IF(Crédits!$K$6<Crédits!$K$7,M5,0))+IF(Crédits!$K$8="",0,IF(Crédits!$K$8<Crédits!$K$7,AC5,0))+IF(Crédits!$K$9="",0,IF(Crédits!$K$9<Crédits!$K$7,AK5,0))+IF(Crédits!$K$10="",0,IF(Crédits!$K$10<Crédits!$K$7,AS5,0)))))) -> 0 | W5: =ROUND(U5-V5,2) -> 3094.47 | X5: =ROUND(X4+Y5-MIN(N(Crédits!$E$7),X4+Y5),2) -> 3094.47 | Y5: =X4*N(Crédits!$D$7)/12 -> 16.383805 | Z5: =AE4 -> 1914.11 | AA5: =Z5*N(Crédits!$D$8)/12 -> 1.91411 | AB5: =MIN(N(Crédits!$E$8),Z5+AA5) -> 95 | AC5: =ROUND(Z5+AA5-AB5,2) -> 1821.02 | AD5: =IF(Crédits!$K$8="",0,MAX(0,MIN(AC5,Plan!$L$7-(IF(Crédits!$K$5="",0,IF(Crédits!$K$5<Crédits!$K$8,E5,0))+IF(Crédits!$K$6="",0,IF(Crédits!$K$6<Crédits!$K$8,M5,0))+IF(Crédits!$K$7="",0,IF(Crédits!$K$7<Crédits!$K$8,U5,0))+IF(Crédits!$K$9="",0,IF(Crédits!$K$9<Crédits!$K$8,AK5,0))+IF(Crédits!$K$10="",0,IF(Crédits!$K$10<Crédits!$K$8,AS5,0)))))) -> 0 | AE5: =ROUND(AC5-AD5,2) -> 1821.02 | AF5: =ROUND(AF4+AG5-MIN(N(Crédits!$E$8),AF4+AG5),2) -> 1821.02 | AG5: =AF4*N(Crédits!$D$8)/12 -> 1.91411 | AH5: =AM4 -> 300 | AI5: =AH5*N(Crédits!$D$9)/12 -> 0 | AJ5: =MIN(N(Crédits!$E$9),AH5+AI5) -> 150 | AK5: =ROUND(AH5+AI5-AJ5,2) -> 150 | AL5: =IF(Crédits!$K$9="",0,MAX(0,MIN(AK5,Plan!$L$7-(IF(Crédits!$K$5="",0,IF(Crédits!$K$5<Crédits!$K$9,E5,0))+IF(Crédits!$K$6="",0,IF(Crédits!$K$6<Crédits!$K$9,M5,0))+IF(Crédits!$K$7="",0,IF(Crédits!$K$7<Crédits!$K$9,U5,0))+IF(Crédits!$K$8="",0,IF(Crédits!$K$8<Crédits!$K$9,AC5,0))+IF(Crédits!$K$10="",0,IF(Crédits!$K$10<Crédits!$K$9,AS5,0)))))) -> 0 | AM5: =ROUND(AK5-AL5,2) -> 150 | AN5: =ROUND(AN4+AO5-MIN(N(Crédits!$E$9),AN4+AO5),2) -> 150 | AO5: =AN4*N(Crédits!$D$9)/12 -> 0 | AP5: =AU4 -> 150 | AQ5: =AP5*N(Crédits!$D$10)/12 -> 0 | AR5: =MIN(N(Crédits!$E$10),AP5+AQ5) -> 50 | AS5: =ROUND(AP5+AQ5-AR5,2) -> 100 | AT5: =IF(Crédits!$K$10="",0,MAX(0,MIN(AS5,Plan!$L$7-(IF(Crédits!$K$5="",0,IF(Crédits!$K$5<Crédits!$K$10,E5,0))+IF(Crédits!$K$6="",0,IF(Crédits!$K$6<Crédits!$K$10,M5,0))+IF(Crédits!$K$7="",0,IF(Crédits!$K$7<Crédits!$K$10,U5,0))+IF(Crédits!$K$8="",0,IF(Crédits!$K$8<Crédits!$K$10,AC5,0))+IF(Crédits!$K$9="",0,IF(Crédits!$K$9<Crédits!$K$10,AK5,0)))))) -> 0 | AU5: =ROUND(AS5-AT5,2) -> 100 | AV5: =ROUND(AV4+AW5-MIN(N(Crédits!$E$10),AV4+AW5),2) -> 100 | AW5: =AV4*N(Crédits!$D$10)/12 -> 0 | AX5: =D5+L5+T5+AB5+AJ5+AR5 -> 731.45 | AY5: =F5+N5+V5+AD5+AL5+AT5 -> 0 | AZ5: =G5+O5+W5+AE5+AM5+AU5 -> 14445.6 | BA5: =C5+K5+S5+AA5+AI5+AQ5 -> 77.811973 | BB5: =I5+Q5+Y5+AG5+AO5+AW5 -> 77.811973
